Workbook
Name Table1: #REF!

Sheet DIV_A
A1: SIES JUNIOR COLLEGE OF COMMERCE, NERUL
A2: FYJC ( DIV A ) MARKSHEET - 2024-2025
C3: ENGLISH | K3: HINDI / IT | S3: Economics | AA3: B.K. & A/C | AI3: OC | AQ3: MATHS I | AU3: MATHS II | AY3: Maths Total | BG3: SP
A4: ROLL NO | B4: STUDENT NAME | C4: ENG UNIT I | D4: ENG TERM I | E4: ENGUNIT II | F4: ENG INT | G4: ENG ANNUAL | H4: ENG TOT | I4: ENG AVG | J4: ENG GRACE | K4: IT UNIT I | L4: IT TERM I | M4: IT UNIT II | N4: IT Pract | O4: IT Annual | P4: IT Total | Q4: IT AVG | R4: IT GRACE | S4: ECO UNIT I | T4: ECO TERM I | U4: ECO UNIT II | V4: ECO INT | W4: ECO ANNUAL | X4: ECO TOT | Y4: ECO AVG | Z4: ECO GRACE | AA4: BK UNIT I | AB4: BK TERM I | AC4: BK UNIT II | AD4: BK INT | AE4: BK ANNUAL | AF4: BK TOT | AG4: BK AVG | AH4: BK GRACE | AI4: OC UNIT I | AJ4: OC TERM 1 | AK4: OC UNIT II | AL4: OC INT | AM4: OC ANNUAL | AN4: OC TOT | AO4: OC AVG | AP4: OC GRACE | AQ4: UNIT I | AR4: TERM I | AS4: UNIT II | AT4: MATH I ANNUAL | AU4: MATH II UNIT I | AV4: MATH II TERM I | AW4: MATH II UNIT II | AX4: MATH II ANNUAL | AY4: MATHSUNIT I | AZ4: MATHS TERM I | BA4: MATHS UNIT II | BB4: MATHS INT | BC4: MATHS ANNUAL | BD4: MATHS TOT | BE4: MATHS AVG | BF4: MATHS GRACE | BG4: SP UNIT I | BH4: SP TERM I | BI4: SP UNIT II | BJ4: SP INT | BK4: MATHS ANNUAL | BL4: MATHS TOT | BM4: MATHS AVG | BN4: MATHS GRACE | BO4: EVS | BP4: PE | BQ4: Total Grace | BR4: TOTAL | BS4: % | BT4: Result | BU4: Subject
C5: 25 | D5: 50 | E5: 25 | F5: 20 | G5: 80 | H5: 200 | I5: 100 | K5: 25 | L5: 50 | M5: 25 | N5: 20 | O5: 80 | P5: 200 | Q5: 100 | S5: 25 | T5: 50 | U5: 25 | V5: 20 | W5: 80 | X5: 200 | Y5: 100 | AA5: 25 | AB5: 50 | AC5: 25 | AD5: 20 | AE5: 80 | AF5: 200 | AG5: 100 | AI5: 25 | AJ5: 50 | AK5: 25 | AL5: 20 | AM5: 80 | AN5: 200 | AO5: 100 | AQ5: 13 | AR5: 25 | AS5: 12 | AT5: 40 | AU5: 12 | AV5: 25 | AW5: 13 | AX5: 40 | AY5: 25 | AZ5: 50 | BA5: 25 | BB5: 20 | BC5: 80 | BD5: 200 | BE5: 100 | BG5: 25 | BH5: 50 | BI5: 25 | BJ5: 20 | BK5: 80 | BL5: 200 | BM5: 100
A6: 1 | B6: AGRAWAL RITH MUKESH | C6: 20 | D6: 30 | E6: 18 | F6: 18 | G6: 65 | H6: =ROUND(SUM(C6:G6),0) -> 151 | I6: =ROUND(H6/2,0) -> 76 | K6: 21 | L6: 44 | M6: 17 | N6: 18 | O6: 68 | P6: =ROUND(SUM(K6:O6),0) -> 168 | Q6: =ROUND(P6/2,0) -> 84 | S6: 19 | T6: 45 | U6: 22 | V6: 20 | W6: 71 | X6: =ROUND(SUM(S6:W6),0) -> 177 | Y6: =ROUND(X6/2,0) -> 89 | AA6: 25 | AB6: 32 | AC6: 19 | AD6: 19 | AE6: 58 | AF6: =ROUND(SUM(AA6:AE6),0) -> 153 | AG6: =ROUND(AF6/2,0) -> 77 | AI6: 25 | AJ6: 48 | AK6: 22 | AL6: 19 | AM6: 70 | AN6: =ROUND(SUM(AI6:AM6),0) -> 184 | AO6: =ROUND(AN6/2,0) -> 92 | AQ6: 12 | AR6: 21.5 | AS6: 12 | AT6: 31 | AU6: 6 | AV6: 19 | AW6: 5.5 | AX6: 28 | AY6: =ROUND(AQ6+AU6,0) -> 18 | AZ6: =ROUND(AR6+AV6,0) -> 41 | BA6: =ROUND(AS6+AW6,0) -> 18 | BB6: 20 | BC6: =ROUND(AT6+AX6,0) -> 59 | BD6: =SUM(AY6:BC6) -> 156 | BE6: =ROUND(BD6/2,0) -> 78 | BO6: A | BP6: A | BR6: =ROUND(I6+Q6+Y6+AG6+AO6+BE6,0) -> 496 | BS6: =BR6/6 -> 82.666667 | BT6: =IF(BS6>=75,"GRADE I with Distinction",IF(BS6>=60,"GRADE I",IF(BS6>=45,"GRADE II",IF(BS6>=35,"PASS","FAIL")))) -> GRADE I with Distinction
A7: 2 | B7: ARYA PRAVIN SHAH | C7: 14 | D7: 31 | E7: 17 | F7: 18 | G7: 60 | H7: =ROUND(SUM(C7:G7),0) -> 140 | I7: =ROUND(H7/2,0) -> 70 | K7: 22 | L7: 47 | M7: 19 | N7: 20 | O7: 65 | P7: =ROUND(SUM(K7:O7),0) -> 173 | Q7: =ROUND(P7/2,0) -> 87 | S7: 25 | T7: 42 | U7: 21 | V7: 20 | W7: 74 | X7: =ROUND(SUM(S7:W7),0) -> 182 | Y7: =ROUND(X7/2,0) -> 91 | AA7: 22 | AB7: 36 | AC7: 22 | AD7: 19 | AE7: 50 | AF7: =ROUND(SUM(AA7:AE7),0) -> 149 | AG7: =ROUND(AF7/2,0) -> 75 | AI7: 17 | AJ7: 43 | AK7: 18 | AL7: 19 | AM7: 66 | AN7: =ROUND(SUM(AI7:AM7),0) -> 163 | AO7: =ROUND(AN7/2,0) -> 82 | AQ7: 13 | AR7: 24 | AS7: 10 | AT7: 36 | AU7: 12 | AV7: 22.5 | AW7: 11 | AX7: 34 | AY7: =ROUND(AQ7+AU7,0) -> 25 | AZ7: =ROUND(AR7+AV7,0) -> 47 | BA7: =ROUND(AS7+AW7,0) -> 21 | BB7: 20 | BC7: =ROUND(AT7+AX7,0) -> 70 | BD7: =SUM(AY7:BC7) -> 183 | BE7: =ROUND(BD7/2,0) -> 92 | BO7: A | BP7: A | BR7: =ROUND(I7+Q7+Y7+AG7+AO7+BE7,0) -> 497 | BS7: =BR7/6 -> 82.833333 | BT7: =IF(BS7>=75,"GRADE I with Distinction",IF(BS7>=60,"GRADE I",IF(BS7>=45,"GRADE II",IF(BS7>=35,"PASS","FAIL")))) -> GRADE I with Distinction
A8: 3 | B8: BARI DRUSHTI PRAFULL | C8: 12 | D8: 36 | E8: 20 | F8: 16 | G8: 73 | H8: =ROUND(SUM(C8:G8),0) -> 157 | I8: =ROUND(H8/2,0) -> 79 | K8: 16 | L8: 43 | M8: 16 | N8: 20 | O8: 48 | P8: =ROUND(SUM(K8:O8),0) -> 143 | Q8: =ROUND(P8/2,0) -> 72 | S8: 24 | T8: 43 | U8: 21 | V8: 20 | W8: 75 | X8: =ROUND(SUM(S8:W8),0) -> 183 | Y8: =ROUND(X8/2,0) -> 92 | AA8: 25 | AB8: 43 | AC8: 21 | AD8: 17 | AE8: 71 | AF8: =ROUND(SUM(AA8:AE8),0) -> 177 | AG8: =ROUND(AF8/2,0) -> 89 | AI8: 25 | AJ8: 49 | AK8: 21 | AL8: 18 | AM8: 74 | AN8: =ROUND(SUM(AI8:AM8),0) -> 187 | AO8: =ROUND(AN8/2,0) -> 94 | AQ8: 13 | AR8: 24 | AS8: 9 | AT8: 32 | AU8: 10 | AV8: 23 | AW8: 9.5 | AX8: 36 | AY8: =ROUND(AQ8+AU8,0) -> 23 | AZ8: =ROUND(AR8+AV8,0) -> 47 | BA8: =ROUND(AS8+AW8,0) -> 19 | BB8: 16 | BC8: =ROUND(AT8+AX8,0) -> 68 | BD8: =SUM(AY8:BC8) -> 173 | BE8: =ROUND(BD8/2,0) -> 87 | BO8: A | BP8: A | BR8: =ROUND(I8+Q8+Y8+AG8+AO8+BE8,0) -> 513 | BS8: =BR8/6 -> 85.5 | BT8: =IF(BS8>=75,"GRADE I with Distinction",IF(BS8>=60,"GRADE I",IF(BS8>=45,"GRADE II",IF(BS8>=35,"PASS","FAIL")))) -> GRADE I with Distinction
A9: 4 | B9: BAWASKAR ANIKET KASHINATH | C9: 12 | D9: 32 | E9: 16 | F9: 18 | G9: 56 | H9: =ROUND(SUM(C9:G9),0) -> 134 | I9: =ROUND(H9/2,0) -> 67 | K9: 15 | L9: 44 | M9: 9 | N9: 20 | O9: 55 | P9: =ROUND(SUM(K9:O9),0) -> 143 | Q9: =ROUND(P9/2,0) -> 72 | S9: 24 | T9: 46 | U9: 21 | V9: 18 | W9: 73 | X9: =ROUND(SUM(S9:W9),0) -> 182 | Y9: =ROUND(X9/2,0) -> 91 | AA9: 25 | AB9: 34 | AC9: 7 | AD9: 18 | AE9: 45 | AF9: =ROUND(SUM(AA9:AE9),0) -> 129 | AG9: =ROUND(AF9/2,0) -> 65 | AI9: 24 | AJ9: 48 | AK9: 18 | AL9: 20 | AM9: 74 | AN9: =ROUND(SUM(AI9:AM9),0) -> 184 | AO9: =ROUND(AN9/2,0) -> 92 | AQ9: 9 | AR9: 10 | AS9: 5 | AT9: 25 | AU9: 4 | AV9: 14 | AW9: 3 | AX9: 11 | AY9: =ROUND(AQ9+AU9,0) -> 13 | AZ9: =ROUND(AR9+AV9,0) -> 24 | BA9: =ROUND(AS9+AW9,0) -> 8 | BB9: 16 | BC9: =ROUND(AT9+AX9,0) -> 36 | BD9: =SUM(AY9:BC9) -> 97 | BE9: =ROUND(BD9/2,0) -> 49 | BO9: A | BP9: A | BR9: =ROUND(I9+Q9+Y9+AG9+AO9+BE9,0) -> 436 | BS9: =BR9/6 -> 72.666667 | BT9: =IF(BS9>=75,"GRADE I with Distinction",IF(BS9>=60,"GRADE I",IF(BS9>=45,"GRADE II",IF(BS9>=35,"PASS","FAIL")))) -> GRADE I
A10: 5 | B10: BHOLE ARPITA VILAS | C10: 14 | D10: 27 | E10: 16 | F10: 18 | G10: 55 | H10: =ROUND(SUM(C10:G10),0) -> 130 | I10: =ROUND(H10/2,0) -> 65 | K10: 9 | L10: 35 | M10: 11 | N10: 20 | O10: 55 | P10: =ROUND(SUM(K10:O10),0) -> 130 | Q10: =ROUND(P10/2,0) -> 65 | S10: 16 | T10: 41 | U10: 20 | V10: 19 | W10: 56 | X10: =ROUND(SUM(S10:W10),0) -> 152 | Y10: =ROUND(X10/2,0) -> 76 | AA10: 23 | AB10: 33 | AC10: 24 | AD10: 17 | AE10: 48 | AF10: =ROUND(SUM(AA10:AE10),0) -> 145 | AG10: =ROUND(AF10/2,0) -> 73 | AI10: 25 | AJ10: 35 | AK10: 12 | AL10: 19 | AM10: 57 | AN10: =ROUND(SUM(AI10:AM10),0) -> 148 | AO10: =ROUND(AN10/2,0) -> 74 | AQ10: 13 | AR10: 11.5 | AS10: 9 | AT10: 24 | AU10: 9 | AV10: 17.5 | AW10: 4.5 | AX10: 25 | AY10: =ROUND(AQ10+AU10,0) -> 22 | AZ10: =ROUND(AR10+AV10,0) -> 29 | BA10: =ROUND(AS10+AW10,0) -> 14 | BB10: 20 | BC10: =ROUND(AT10+AX10,0) -> 49 | BD10: =SUM(AY10:BC10) -> 134 | BE10: =ROUND(BD10/2,0) -> 67 | BO10: A | BP10: A | BR10: =ROUND(I10+Q10+Y10+AG10+AO10+BE10,0) -> 420 | BS10: =BR10/6 -> 70 | BT10: =IF(BS10>=75,"GRADE I with Distinction",IF(BS10>=60,"GRADE I",IF(BS10>=45,"GRADE II",IF(BS10>=35,"PASS","FAIL")))) -> GRADE I
A11: 6 | B11: BISHT SIMRAN PADAM | C11: 12 | D11: 29 | E11: 14 | F11: 18 | G11: 52 | H11: =ROUND(SUM(C11:G11),0) -> 125 | I11: =ROUND(H11/2,0) -> 63 | K11: 15 | L11: 41 | M11: 17 | N11: 19 | O11: 55 | P11: =ROUND(SUM(K11:O11),0) -> 147 | Q11: =ROUND(P11/2,0) -> 74 | S11: 23 | T11: 42 | U11: 15 | V11: 19 | W11: 65 | X11: =ROUND(SUM(S11:W11),0) -> 164 | Y11: =ROUND(X11/2,0) -> 82 | AA11: 20 | AB11: 26 | AC11: 19 | AD11: 19 | AE11: 44 | AF11: =ROUND(SUM(AA11:AE11),0) -> 128 | AG11: =ROUND(AF11/2,0) -> 64 | AI11: 21 | AJ11: 50 | AK11: 16 | AL11: 20 | AM11: 58 | AN11: =ROUND(SUM(AI11:AM11),0) -> 165 | AO11: =ROUND(AN11/2,0) -> 83 | AQ11: 10 | AR11: 12 | AS11: 5.5 | AT11: 16 | AU11: 9.5 | AV11: 11.5 | AW11: 6 | AX11: 19 | AY11: =ROUND(AQ11+AU11,0) -> 20 | AZ11: =ROUND(AR11+AV11,0) -> 24 | BA11: =ROUND(AS11+AW11,0) -> 12 | BB11: 14 | BC11: =ROUND(AT11+AX11,0) -> 35 | BD11: =SUM(AY11:BC11) -> 105 | BE11: =ROUND(BD11/2,0) -> 53 | BO11: A | BP11: A | BR11: =ROUND(I11+Q11+Y11+AG11+AO11+BE11,0) -> 419 | BS11: =BR11/6 -> 69.833333 | BT11: =IF(BS11>=75,"GRADE I with Distinction",IF(BS11>=60,"GRADE I",IF(BS11>=45,"GRADE II",IF(BS11>=35,"PASS","FAIL")))) -> GRADE I
A12: 7 | B12: DAMA NISHA | C12: 11 | D12: 32 | E12: 19 | F12: 16 | G12: 55 | H12: =ROUND(SUM(C12:G12),0) -> 133 | I12: =ROUND(H12/2,0) -> 67 | K12: 8 | L12: 47 | M12: 10 | N12: 19 | O12: 48 | P12: =ROUND(SUM(K12:O12),0) -> 132 | Q12: =ROUND(P12/2,0) -> 66 | S12: 23 | T12: 42 | U12: 18 | V12: 19 | W12: 72 | X12: =ROUND(SUM(S12:W12),0) -> 174 | Y12: =ROUND(X12/2,0) -> 87 | AA12: 17 | AB12: 18 | AC12: 10 | AD12: 17 | AE12: 41 | AF12: =ROUND(SUM(AA12:AE12),0) -> 103 | AG12: =ROUND(AF12/2,0) -> 52 | AI12: 19 | AJ12: 45 | AK12: 16 | AL12: 17 | AM12: 64 | AN12: =ROUND(SUM(AI12:AM12),0) -> 161 | AO12: =ROUND(AN12/2,0) -> 81 | AS12: SP | AW12: SP | AX12: SP | BG12: 0 | BH12: 15 | BI12: 13 | BJ12: 16 | BK12: 66 | BL12: =SUM(BG12:BK12) -> 110 | BM12: =110/2 -> 55 | BO12: A | BP12: A | BR12: =ROUND(I12+Q12+Y12+AG12+AO12+BE12,0) -> 353 | BS12: =BR12/6 -> 58.833333 | BT12: =IF(BS12>=75,"GRADE I with Distinction",IF(BS12>=60,"GRADE I",IF(BS12>=45,"GRADE II",IF(BS12>=35,"PASS","FAIL")))) -> GRADE II
A13: 8 | B13: DAVID JOHN | C13: 10 | D13: 29 | E13: 16 | F13: 16 | G13: 57 | H13: =ROUND(SUM(C13:G13),0) -> 128 | I13: =ROUND(H13/2,0) -> 64 | K13: 20 | L13: 48 | M13: 18 | N13: 20 | O13: 76 | P13: =ROUND(SUM(K13:O13),0) -> 182 | Q13: =ROUND(P13/2,0) -> 91 | S13: 25 | T13: 44 | U13: 21 | V13: 19 | W13: 74 | X13: =ROUND(SUM(S13:W13),0) -> 183 | Y13: =ROUND(X13/2,0) -> 92 | AA13: 25 | AB13: 43 | AC13: 25 | AD13: 19 | AE13: 73 | AF13: =ROUND(SUM(AA13:AE13),0) -> 185 | AG13: =ROUND(AF13/2,0) -> 93 | AI13: 25 | AJ13: 50 | AK13: 25 | AL13: 20 | AM13: 79 | AN13: =ROUND(SUM(AI13:AM13),0) -> 199 | AO13: =ROUND(AN13/2,0) -> 100 | AQ13: 10 | AR13: 25 | AS13: 9 | AT13: 30 | AU13: 11 | AV13: 24.5 | AW13: 9 | AX13: 39 | AY13: =ROUND(AQ13+AU13,0) -> 21 | AZ13: =ROUND(AR13+AV13,0) -> 50 | BA13: =ROUND(AS13+AW13,0) -> 18 | BB13: 20 | BC13: =ROUND(AT13+AX13,0) -> 69 | BD13: =SUM(AY13:BC13) -> 178 | BE13: =ROUND(BD13/2,0) -> 89 | BO13: A | BP13: A | BR13: =ROUND(I13+Q13+Y13+AG13+AO13+BE13,0) -> 529 | BS13: =BR13/6 -> 88.166667 | BT13: =IF(BS13>=75,"GRADE I with Distinction",IF(BS13>=60,"GRADE I",IF(BS13>=45,"GRADE II",IF(BS13>=35,"PASS","FAIL")))) -> GRADE I with Distinction
A14: 9 | B14: DHANDRUT MANSI GANESH | C14: 13 | D14: 30 | E14: 14 | F14: 10 | G14: 50 | H14: =ROUND(SUM(C14:G14),0) -> 117 | I14: =ROUND(H14/2,0) -> 59 | K14: 12 | L14: 40 | M14: 13 | N14: 20 | O14: 61 | P14: =ROUND(SUM(K14:O14),0) -> 146 | Q14: =ROUND(P14/2,0) -> 73 | S14: 24 | T14: 45 | U14: 22 | V14: 19 | W14: 67 | X14: =ROUND(SUM(S14:W14),0) -> 177 | Y14: =ROUND(X14/2,0) -> 89 | AA14: 22 | AB14: 34 | AC14: 18 | AD14: 17 | AE14: 47 | AF14: =ROUND(SUM(AA14:AE14),0) -> 138 | AG14: =ROUND(AF14/2,0) -> 69 | AI14: 24 | AJ14: 47 | AK14: 21 | AL14: 20 | AM14: 60 | AN14: =ROUND(SUM(AI14:AM14),0) -> 172 | AO14: =ROUND(AN14/2,0) -> 86 | AQ14: 12 | AR14: 7 | AS14: 3.5 | AT14: 20 | AU14: 8 | AV14: 19.5 | AW14: 8 | AX14: 7 | AY14: =ROUND(AQ14+AU14,0) -> 20 | AZ14: =ROUND(AR14+AV14,0) -> 27 | BA14: =ROUND(AS14+AW14,0) -> 12 | BB14: 15 | BC14: =ROUND(AT14+AX14,0) -> 27 | BD14: =SUM(AY14:BC14) -> 101 | BE14: =ROUND(BD14/2,0) -> 51 | BO14: A | BP14: A | BR14: =ROUND(I14+Q14+Y14+AG14+AO14+BE14,0) -> 427 | BS14: =BR14/6 -> 71.166667 | BT14: =IF(BS14>=75,"GRADE I with Distinction",IF(BS14>=60,"GRADE I",IF(BS14>=45,"GRADE II",IF(BS14>=35,"PASS","FAIL")))) -> GRADE I
A15: 10 | B15: DUDWADKAR ARCHITA MAHESH | C15: 10 | D15: 28 | E15: 17 | F15: 15 | G15: 49 | H15: =ROUND(SUM(C15:G15),0) -> 119 | I15: =ROUND(H15/2,0) -> 60 | K15: 17 | L15: 38 | M15: 16 | N15: 19 | O15: 62 | P15: =ROUND(SUM(K15:O15),0) -> 152 | Q15: =ROUND(P15/2,0) -> 76 | S15: 23 | T15: 42 | U15: 15 | V15: 19 | W15: 66 | X15: =ROUND(SUM(S15:W15),0) -> 165 | Y15: =ROUND(X15/2,0) -> 83 | AA15: 24 | AB15: 39 | AC15: 19 | AD15: 18 | AE15: 50 | AF15: =ROUND(SUM(AA15:AE15),0) -> 150 | AG15: =ROUND(AF15/2,0) -> 75 | AI15: 23 | AJ15: 45 | AK15: 17 | AL15: 19 | AM15: 62 | AN15: =ROUND(SUM(AI15:AM15),0) -> 166 | AO15: =ROUND(AN15/2,0) -> 83 | AQ15: 10 | AR15: 22 | AS15: 10 | AT15: 32 | AU15: 7.5 | AV15: 22.5 | AW15: 9 | AX15: 32 | AY15: =ROUND(AQ15+AU15,0) -> 18 | AZ15: =ROUND(AR15+AV15,0) -> 45 | BA15: =ROUND(AS15+AW15,0) -> 19 | BB15: 19 | BC15: =ROUND(AT15+AX15,0) -> 64 | BD15: =SUM(AY15:BC15) -> 165 | BE15: =ROUND(BD15/2,0) -> 83 | BO15: A | BP15: A | BR15: =ROUND(I15+Q15+Y15+AG15+AO15+BE15,0) -> 460 | BS15: =BR15/6 -> 76.666667 | BT15: =IF(BS15>=75,"GRADE I with Distinction",IF(BS15>=60,"GRADE I",IF(BS15>=45,"GRADE II",IF(BS15>=35,"PASS","FAIL")))) -> GRADE I with Distinction
A16: 11 | B16: GAMI KRISHNA JEETU | C16: 15 | D16: 32 | E16: 19 | F16: 15 | G16: 48 | H16: =ROUND(SUM(C16:G16),0) -> 129 | I16: =ROUND(H16/2,0) -> 65 | K16: 13 | L16: 31 | M16: 13 | N16: 18 | O16: 48 | P16: =ROUND(SUM(K16:O16),0) -> 123 | Q16: =ROUND(P16/2,0) -> 62 | S16: 21 | T16: 40 | U16: 16 | V16: 15 | W16: 63 | X16: =ROUND(SUM(S16:W16),0) -> 155 | Y16: =ROUND(X16/2,0) -> 78 | AA16: 15 | AB16: 36 | AC16: 21 | AD16: 17 | AE16: 41 | AF16: =ROUND(SUM(AA16:AE16),0) -> 130 | AG16: =ROUND(AF16/2,0) -> 65 | AI16: 18 | AJ16: 32 | AK16: 15 | AL16: 17 | AM16: 49 | AN16: =ROUND(SUM(AI16:AM16),0) -> 131 | AO16: =ROUND(AN16/2,0) -> 66 | AQ16: 6.5 | AR16: 17 | AS16: 6.5 | AT16: 17 | AU16: 7.5 | AV16: 18.5 | AW16: 7.5 | AX16: 29 | AY16: =ROUND(AQ16+AU16,0) -> 14 | AZ16: =ROUND(AR16+AV16,0) -> 36 | BA16: =ROUND(AS16+AW16,0) -> 14 | BB16: 16 | BC16: =ROUND(AT16+AX16,0) -> 46 | BD16: =SUM(AY16:BC16) -> 126 | BE16: =ROUND(BD16/2,0) -> 63 | BO16: A | BP16: A | BR16: =ROUND(I16+Q16+Y16+AG16+AO16+BE16,0) -> 399 | BS16: =BR16/6 -> 66.5 | BT16: =IF(BS16>=75,"GRADE I with Distinction",IF(BS16>=60,"GRADE I",IF(BS16>=45,"GRADE II",IF(BS16>=35,"PASS","FAIL")))) -> GRADE I
A17: 12 | B17: GHAG VISHNU MAHENDRA | C17: 11 | D17: 27 | E17: 16 | F17: 14 | G17: 48 | H17: =ROUND(SUM(C17:G17),0) -> 116 | I17: =ROUND(H17/2,0) -> 58 | K17: 13 | L17: 34 | M17: 19 | N17: 18 | O17: 52 | P17: =ROUND(SUM(K17:O17),0) -> 136 | Q17: =ROUND(P17/2,0) -> 68 | S17: 25 | T17: 48 | U17: 23 | V17: 17 | W17: 70 | X17: =ROUND(SUM(S17:W17),0) -> 183 | Y17: =ROUND(X17/2,0) -> 92 | AA17: 21 | AB17: 36 | AC17: 19 | AD17: 20 | AE17: 52 | AF17: =ROUND(SUM(AA17:AE17),0) -> 148 | AG17: =ROUND(AF17/2,0) -> 74 | AI17: 25 | AJ17: 49 | AK17: 25 | AL17: 19 | AM17: 63 | AN17: =ROUND(SUM(AI17:AM17),0) -> 181 | AO17: =ROUND(AN17/2,0) -> 91 | AQ17: 12 | AR17: 25 | AS17: 10 | AT17: 29 | AU17: 9 | AV17: 21 | AW17: 7.5 | AX17: 24 | AY17: =ROUND(AQ17+AU17,0) -> 21 | AZ17: =ROUND(AR17+AV17,0) -> 46 | BA17: =ROUND(AS17+AW17,0) -> 18 | BB17: 20 | BC17: =ROUND(AT17+AX17,0) -> 53 | BD17: =SUM(AY17:BC17) -> 158 | BE17: =ROUND(BD17/2,0) -> 79 | BO17: A | BP17: A | BR17: =ROUND(I17+Q17+Y17+AG17+AO17+BE17,0) -> 462 | BS17: =BR17/6 -> 77 | BT17: =IF(BS17>=75,"GRADE I with Distinction",IF(BS17>=60,"GRADE I",IF(BS17>=45,"GRADE II",IF(BS17>=35,"PASS","FAIL")))) -> GRADE I with Distinction
A18: 13 | B18: GHORPADE SAMRUDHI SACHIN | C18: 12 | D18: 26 | E18: 18 | F18: 16 | G18: 51 | H18: =ROUND(SUM(C18:G18),0) -> 123 | I18: =ROUND(H18/2,0) -> 62 | K18: 13 | L18: 45 | M18: 22 | N18: 20 | O18: 57 | P18: =ROUND(SUM(K18:O18),0) -> 157 | Q18: =ROUND(P18/2,0) -> 79 | S18: 22 | T18: 44 | U18: 21 | V18: 19 | W18: 72 | X18: =ROUND(SUM(S18:W18),0) -> 178 | Y18: =ROUND(X18/2,0) -> 89 | AA18: 24 | AB18: 35 | AC18: 21 | AD18: 17 | AE18: 63 | AF18: =ROUND(SUM(AA18:AE18),0) -> 160 | AG18: =ROUND(AF18/2,0) -> 80 | AI18: 20 | AJ18: 49 | AK18: 24 | AL18: 20 | AM18: 69 | AN18: =ROUND(SUM(AI18:AM18),0) -> 182 | AO18: =ROUND(AN18/2,0) -> 91 | AQ18: 13 | AR18: 14 | AS18: 12 | AT18: 33 | AU18: 10 | AV18: 23 | AW18: 10.5 | AX18: 23 | AY18: =ROUND(AQ18+AU18,0) -> 23 | AZ18: =ROUND(AR18+AV18,0) -> 37 | BA18: =ROUND(AS18+AW18,0) -> 23 | BB18: 20 | BC18: =ROUND(AT18+AX18,0) -> 56 | BD18: =SUM(AY18:BC18) -> 159 | BE18: =ROUND(BD18/2,0) -> 80 | BO18: B | BP18: A | BR18: =ROUND(I18+Q18+Y18+AG18+AO18+BE18,0) -> 481 | BS18: =BR18/6 -> 80.166667 | BT18: =IF(BS18>=75,"GRADE I with Distinction",IF(BS18>=60,"GRADE I",IF(BS18>=45,"GRADE II",IF(BS18>=35,"PASS","FAIL")))) -> GRADE I with Distinction
A19: 14 | B19: GUNJ RAJU VORA | C19: 10 | D19: 28 | E19: 14 | F19: 12 | G19: 55 | H19: =ROUND(SUM(C19:G19),0) -> 119 | I19: =ROUND(H19/2,0) -> 60 | K19: 15 | L19: 36 | M19: 11 | N19: 20 | O19: 64 | P19: =ROUND(SUM(K19:O19),0) -> 146 | Q19: =ROUND(P19/2,0) -> 73 | S19: 22 | T19: 43 | U19: 15 | V19: 18 | W19: 68 | X19: =ROUND(SUM(S19:W19),0) -> 166 | Y19: =ROUND(X19/2,0) -> 83 | AA19: 16 | AB19: 24 | AC19: 5 | AD19: 16 | AE19: 50 | AF19: =ROUND(SUM(AA19:AE19),0) -> 111 | AG19: =ROUND(AF19/2,0) -> 56 | AI19: 20 | AJ19: 47 | AK19: 19 | AL19: 17 | AM19: 63 | AN19: =ROUND(SUM(AI19:AM19),0) -> 166 | AO19: =ROUND(AN19/2,0) -> 83 | AQ19: 9 | AR19: 20.5 | AS19: 8.5 | AT19: 22 | AU19: 5 | AV19: 11.5 | AW19: 9.5 | AX19: 33 | AY19: =ROUND(AQ19+AU19,0) -> 14 | AZ19: =ROUND(AR19+AV19,0) -> 32 | BA19: =ROUND(AS19+AW19,0) -> 18 | BB19: 14 | BC19: =ROUND(AT19+AX19,0) -> 55 | BD19: =SUM(AY19:BC19) -> 133 | BE19: =ROUND(BD19/2,0) -> 67 | BO19: A | BP19: A | BR19: =ROUND(I19+Q19+Y19+AG19+AO19+BE19,0) -> 422 | BS19: =BR19/6 -> 70.333333 | BT19: =IF(BS19>=75,"GRADE I with Distinction",IF(BS19>=60,"GRADE I",IF(BS19>=45,"GRADE II",IF(BS19>=35,"PASS","FAIL")))) -> GRADE I
A20: 15 | B20: HAMDULAY ZAINULABIDIN ZUBAIR | C20: 13 | D20: 34 | E20: 19 | F20: 15 | G20: 58 | H20: =ROUND(SUM(C20:G20),0) -> 139 | I20: =ROUND(H20/2,0) -> 70 | K20: 20 | L20: 46 | M20: 12 | N20: 18 | O20: 56 | P20: =ROUND(SUM(K20:O20),0) -> 152 | Q20: =ROUND(P20/2,0) -> 76 | S20: 24 | T20: 47 | U20: 20 | V20: 20 | W20: 67 | X20: =ROUND(SUM(S20:W20),0) -> 178 | Y20: =ROUND(X20/2,0) -> 89 | AA20: 25 | AB20: 37 | AC20: 25 | AD20: 17 | AE20: 53 | AF20: =ROUND(SUM(AA20:AE20),0) -> 157 | AG20: =ROUND(AF20/2,0) -> 79 | AI20: 25 | AJ20: 50 | AK20: 19 | AL20: 18 | AM20: 75 | AN20: =ROUND(SUM(AI20:AM20),0) -> 187 | AO20: =ROUND(AN20/2,0) -> 94 | AQ20: 12 | AR20: 21.5 | AS20: 12 | AT20: 37 | AU20: 12 | AV20: 23 | AW20: 6 | AX20: 28 | AY20: =ROUND(AQ20+AU20,0) -> 24 | AZ20: =ROUND(AR20+AV20,0) -> 45 | BA20: =ROUND(AS20+AW20,0) -> 18 | BB20: 16 | BC20: =ROUND(AT20+AX20,0) -> 65 | BD20: =SUM(AY20:BC20) -> 168 | BE20: =ROUND(BD20/2,0) -> 84 | BO20: A | BP20: A | BR20: =ROUND(I20+Q20+Y20+AG20+AO20+BE20,0) -> 492 | BS20: =BR20/6 -> 82 | BT20: =IF(BS20>=75,"GRADE I with Distinction",IF(BS20>=60,"GRADE I",IF(BS20>=45,"GRADE II",IF(BS20>=35,"PASS","FAIL")))) -> GRADE I with Distinction
A21: 16 | B21: KAMBLE SUMEDH MANGESH | C21: 11 | D21: 28 | E21: 17 | F21: 16 | G21: 52 | H21: =ROUND(SUM(C21:G21),0) -> 124 | I21: =ROUND(H21/2,0) -> 62 | K21: 11 | L21: 40 | M21: 8 | N21: 18 | O21: 65 | P21: =ROUND(SUM(K21:O21),0) -> 142 | Q21: =ROUND(P21/2,0) -> 71 | S21: 25 | T21: 42 | U21: 20 | V21: 19 | W21: 63 | X21: =ROUND(SUM(S21:W21),0) -> 169 | Y21: =ROUND(X21/2,0) -> 85 | AA21: 23 | AB21: 37 | AC21: 16 | AD21: 18 | AE21: 63 | AF21: =ROUND(SUM(AA21:AE21),0) -> 157 | AG21: =ROUND(AF21/2,0) -> 79 | AI21: 23 | AJ21: 48 | AK21: 19 | AL21: 17 | AM21: 58 | AN21: =ROUND(SUM(AI21:AM21),0) -> 165 | AO21: =ROUND(AN21/2,0) -> 83 | AQ21: 12 | AR21: 10 | AS21: 7.5 | AT21: 30 | AU21: 9 | AV21: 23 | AW21: 7.5 | AX21: 30 | AY21: =ROUND(AQ21+AU21,0) -> 21 | AZ21: =ROUND(AR21+AV21,0) -> 33 | BA21: =ROUND(AS21+AW21,0) -> 15 | BB21: 16 | BC21: =ROUND(AT21+AX21,0) -> 60 | BD21: =SUM(AY21:BC21) -> 145 | BE21: =ROUND(BD21/2,0) -> 73 | BO21: A | BP21: A | BR21: =ROUND(I21+Q21+Y21+AG21+AO21+BE21,0) -> 453 | BS21: =BR21/6 -> 75.5 | BT21: =IF(BS21>=75,"GRADE I with Distinction",IF(BS21>=60,"GRADE I",IF(BS21>=45,"GRADE II",IF(BS21>=35,"PASS","FAIL")))) -> GRADE I with Distinction
A22: 17 | B22: KANOJIA MEHUL VIRENDRA | C22: 15 | D22: 31 | E22: 20 | F22: 18 | G22: 58 | H22: =ROUND(SUM(C22:G22),0) -> 142 | I22: =ROUND(H22/2,0) -> 71 | K22: 15 | L22: 37 | M22: 18 | N22: 17 | O22: 60 | P22: =ROUND(SUM(K22:O22),0) -> 147 | Q22: =ROUND(P22/2,0) -> 74 | S22: 24 | T22: 43 | U22: 20 | V22: 19 | W22: 74 | X22: =ROUND(SUM(S22:W22),0) -> 180 | Y22: =ROUND(X22/2,0) -> 90 | AA22: 18 | AB22: 38 | AC22: 23 | AD22: 18 | AE22: 47 | AF22: =ROUND(SUM(AA22:AE22),0) -> 144 | AG22: =ROUND(AF22/2,0) -> 72 | AI22: 19 | AJ22: 49 | AK22: 23 | AL22: 19 | AM22: 75 | AN22: =ROUND(SUM(AI22:AM22),0) -> 185 | AO22: =ROUND(AN22/2,0) -> 93 | AQ22: 10 | AR22: 18.5 | AS22: 8 | AT22: 24 | AU22: 8 | AV22: 23.5 | AW22: 7 | AX22: 34 | AY22: =ROUND(AQ22+AU22,0) -> 18 | AZ22: =ROUND(AR22+AV22,0) -> 42 | BA22: =ROUND(AS22+AW22,0) -> 15 | BB22: 18 | BC22: =ROUND(AT22+AX22,0) -> 58 | BD22: =SUM(AY22:BC22) -> 151 | BE22: =ROUND(BD22/2,0) -> 76 | BO22: A | BP22: A | BR22: =ROUND(I22+Q22+Y22+AG22+AO22+BE22,0) -> 476 | BS22: =BR22/6 -> 79.333333 | BT22: =IF(BS22>=75,"GRADE I with Distinction",IF(BS22>=60,"GRADE I",IF(BS22>=45,"GRADE II",IF(BS22>=35,"PASS","FAIL")))) -> GRADE I with Distinction
A23: 18 | B23: KANSAL PALAK SANJAY | C23: 18 | D23: 34 | E23: 18 | F23: 16 | G23: 59 | H23: =ROUND(SUM(C23:G23),0) -> 145 | I23: =ROUND(H23/2,0) -> 73 | K23: 21 | L23: 48 | M23: 21 | N23: 18 | O23: 73 | P23: =ROUND(SUM(K23:O23),0) -> 181 | Q23: =ROUND(P23/2,0) -> 91 | S23: 25 | T23: 46 | U23: 22 | V23: 20 | W23: 75 | X23: =ROUND(SUM(S23:W23),0) -> 188 | Y23: =ROUND(X23/2,0) -> 94 | AA23: 23 | AB23: 43 | AC23: 24 | AD23: 18 | AE23: 71 | AF23: =ROUND(SUM(AA23:AE23),0) -> 179 | AG23: =ROUND(AF23/2,0) -> 90 | AI23: 24 | AJ23: 50 | AK23: 21 | AL23: 20 | AM23: 77 | AN23: =ROUND(SUM(AI23:AM23),0) -> 192 | AO23: =ROUND(AN23/2,0) -> 96 | AQ23: 13 | AR23: 24 | AS23: 11 | AT23: 37 | AU23: 10 | AV23: 24.5 | AW23: 8.5 | AX23: 34 | AY23: =ROUND(AQ23+AU23,0) -> 23 | AZ23: =ROUND(AR23+AV23,0) -> 49 | BA23: =ROUND(AS23+AW23,0) -> 20 | BB23: 20 | BC23: =ROUND(AT23+AX23,0) -> 71 | BD23: =SUM(AY23:BC23) -> 183 | BE23: =ROUND(BD23/2,0) -> 92 | BO23: A | BP23: A | BR23: =ROUND(I23+Q23+Y23+AG23+AO23+BE23,0) -> 536 | BS23: =BR23/6 -> 89.333333 | BT23: =IF(BS23>=75,"GRADE I with Distinction",IF(BS23>=60,"GRADE I",IF(BS23>=45,"GRADE II",IF(BS23>=35,"PASS","FAIL")))) -> GRADE I with Distinction
A24: 19 | B24: KARMARKAR MANAVA AMEYA | C24: 18 | D24: 33 | E24: 17 | F24: 18 | G24: 51 | H24: =ROUND(SUM(C24:G24),0) -> 137 | I24: =ROUND(H24/2,0) -> 69 | K24: 21 | L24: 44 | M24: 20 | N24: 20 | O24: 63 | P24: =ROUND(SUM(K24:O24),0) -> 168 | Q24: =ROUND(P24/2,0) -> 84 | S24: 23 | T24: 46 | U24: 21 | V24: 16 | W24: 65 | X24: =ROUND(SUM(S24:W24),0) -> 171 | Y24: =ROUND(X24/2,0) -> 86 | AA24: 24 | AB24: 18 | AC24: 7 | AD24: 14 | AE24: 29 | AF24: =ROUND(SUM(AA24:AE24),0) -> 92 | AG24: =ROUND(AF24/2,0) -> 46 | AI24: 21 | AJ24: 40 | AK24: 17 | AL24: 20 | AM24: 69 | AN24: =ROUND(SUM(AI24:AM24),0) -> 167 | AO24: =ROUND(AN24/2,0) -> 84 | AQ24: 12 | AR24: 12 | AS24: 8.5 | AT24: 33 | AU24: 11 | AV24: 13.5 | AW24: 5.5 | AX24: 28 | AY24: =ROUND(AQ24+AU24,0) -> 23 | AZ24: =ROUND(AR24+AV24,0) -> 26 | BA24: =ROUND(AS24+AW24,0) -> 14 | BB24: 19 | BC24: =ROUND(AT24+AX24,0) -> 61 | BD24: =SUM(AY24:BC24) -> 143 | BE24: =ROUND(BD24/2,0) -> 72 | BO24: A | BP24: A | BR24: =ROUND(I24+Q24+Y24+AG24+AO24+BE24,0) -> 441 | BS24: =BR24/6 -> 73.5 | BT24: =IF(BS24>=75,"GRADE I with Distinction",IF(BS24>=60,"GRADE I",IF(BS24>=45,"GRADE II",IF(BS24>=35,"PASS","FAIL")))) -> GRADE I
... A29: 24 | B29: MAGDUM JANHAVI SHAILESH | C29: 15 | D29: 29 | E29: 18 | F29: 16 | G29: 61 | H29: =ROUND(SUM(C29:G29),0) -> 139 | I29: =ROUND(H29/2,0) -> 70 | K29: 20 | L29: 47 | M29: 12 | N29: 17 | O29: 59 | P29: =ROUND(SUM(K29:O29),0) -> 155 | Q29: =ROUND(P29/2,0) -> 78 | S29: 23 | T29: 43 | U29: 21 | V29: 18 | W29: 75 | X29: =ROUND(SUM(S29:W29),0) -> 180 | Y29: =ROUND(X29/2,0) -> 90 | AA29: 24 | AB29: 26 | AC29: 24 | AD29: 17 | AE29: 46 | AF29: =ROUND(SUM(AA29:AE29),0) -> 137 | AG29: =ROUND(AF29/2,0) -> 69 | AI29: 21 | AJ29: 48 | AK29: 17 | AL29: 20 | AM29: 66 | AN29: =ROUND(SUM(AI29:AM29),0) -> 172 | AO29: =ROUND(AN29/2,0) -> 86 | AQ29: 12 | AR29: 18.5 | AS29: 5 | AT29: 24 | AU29: 11.5 | AV29: 14 | AW29: 10.5 | AX29: 23 | AY29: =ROUND(AQ29+AU29,0) -> 24 | AZ29: =ROUND(AR29+AV29,0) -> 33 | BA29: =ROUND(AS29+AW29,0) -> 16 | BB29: 17 | BC29: =ROUND(AT29+AX29,0) -> 47 | BD29: =SUM(AY29:BC29) -> 137 | BE29: =ROUND(BD29/2,0) -> 69 | BO29: A | BP29: A | BR29: =ROUND(I29+Q29+Y29+AG29+AO29+BE29,0) -> 462 | BS29: =BR29/6 -> 77 | BT29: =IF(BS29>=75,"GRADE I with Distinction",IF(BS29>=60,"GRADE I",IF(BS29>=45,"GRADE II",IF(BS29>=35,"PASS","FAIL")))) -> GRADE I with Distinction
A30: 25 | B30: MALI AARUSHI NILESH | C30: 21 | D30: 39 | E30: 0 | F30: 16 | G30: 64 | H30: =ROUND(SUM(C30:G30),0) -> 140 | I30: =ROUND(H30/2,0) -> 70 | K30: 21 | L30: 42 | M30: 0 | N30: 19 | O30: 64 | P30: =ROUND(SUM(K30:O30),0) -> 146 | Q30: =ROUND(P30/2,0) -> 73 | S30: 24 | T30: 42 | U30: 0 | V30: 19 | W30: 69 | X30: =ROUND(SUM(S30:W30),0) -> 154 | Y30: =ROUND(X30/2,0) -> 77 | AA30: 24 | AB30: 36 | AC30: 0 | AD30: 20 | AE30: 62 | AF30: =ROUND(SUM(AA30:AE30),0) -> 142 | AG30: =ROUND(AF30/2,0) -> 71 | AI30: 24 | AJ30: 48 | AK30: 0 | AL30: 16 | AM30: 71 | AN30: =ROUND(SUM(AI30:AM30),0) -> 159 | AO30: =ROUND(AN30/2,0) -> 80 | AQ30: 13 | AR30: 25 | AS30: 0 | AT30: 33 | AU30: 12 | AV30: 23.5 | AW30: 0 | AX30: 34 | AY30: =ROUND(AQ30+AU30,0) -> 25 | AZ30: =ROUND(AR30+AV30,0) -> 49 | BA30: 0 | BB30: 20 | BC30: =ROUND(AT30+AX30,0) -> 67 | BD30: =SUM(AY30:BC30) -> 161 | BE30: =ROUND(BD30/2,0) -> 81 | BO30: A | BP30: A | BR30: =ROUND(I30+Q30+Y30+AG30+AO30+BE30,0) -> 452 | BS30: =BR30/6 -> 75.333333 | BT30: =IF(BS30>=75,"GRADE I with Distinction",IF(BS30>=60,"GRADE I",IF(BS30>=45,"GRADE II",IF(BS30>=35,"PASS","FAIL")))) -> GRADE I with Distinction
A31: 26 | B31: MAURYA VAISHNAVI DASHARATH | C31: 15 | D31: 34 | E31: 21 | F31: 16 | G31: 61 | H31: =ROUND(SUM(C31:G31),0) -> 147 | I31: =ROUND(H31/2,0) -> 74 | K31: 19 | L31: 47 | M31: 18 | N31: 20 | O31: 59 | P31: =ROUND(SUM(K31:O31),0) -> 163 | Q31: =ROUND(P31/2,0) -> 82 | S31: 25 | T31: 47 | U31: 22 | V31: 19 | W31: 73 | X31: =ROUND(SUM(S31:W31),0) -> 186 | Y31: =ROUND(X31/2,0) -> 93 | AA31: 24 | AB31: 32 | AC31: 20 | AD31: 19 | AE31: 68 | AF31: =ROUND(SUM(AA31:AE31),0) -> 163 | AG31: =ROUND(AF31/2,0) -> 82 | AI31: 24 | AJ31: 46 | AK31: 23 | AL31: 19 | AM31: 74 | AN31: =ROUND(SUM(AI31:AM31),0) -> 186 | AO31: =ROUND(AN31/2,0) -> 93 | AQ31: 13 | AR31: 23 | AS31: 6 | AT31: 33 | AU31: 11 | AV31: 20 | AW31: 8.5 | AX31: 28 | AY31: =ROUND(AQ31+AU31,0) -> 24 | AZ31: =ROUND(AR31+AV31,0) -> 43 | BA31: =ROUND(AS31+AW31,0) -> 15 | BB31: 18 | BC31: =ROUND(AT31+AX31,0) -> 61 | BD31: =SUM(AY31:BC31) -> 161 | BE31: =ROUND(BD31/2,0) -> 81 | BO31: A | BP31: A | BR31: =ROUND(I31+Q31+Y31+AG31+AO31+BE31,0) -> 505 | BS31: =BR31/6 -> 84.166667 | BT31: =IF(BS31>=75,"GRADE I with Distinction",IF(BS31>=60,"GRADE I",IF(BS31>=45,"GRADE II",IF(BS31>=35,"PASS","FAIL")))) -> GRADE I with Distinction
A32: 27 | B32: MERA TEJAS GOVIND | C32: 16 | D32: 36 | E32: 19 | F32: 14 | G32: 58 | H32: =ROUND(SUM(C32:G32),0) -> 143 | I32: =ROUND(H32/2,0) -> 72 | K32: 20 | L32: 43 | M32: 12 | N32: 18 | O32: 63 | P32: =ROUND(SUM(K32:O32),0) -> 156 | Q32: =ROUND(P32/2,0) -> 78 | S32: 25 | T32: 48 | U32: 21 | V32: 20 | W32: 72 | X32: =ROUND(SUM(S32:W32),0) -> 186 | Y32: =ROUND(X32/2,0) -> 93 | AA32: 22 | AB32: 26 | AC32: 18 | AD32: 11 | AE32: 42 | AF32: =ROUND(SUM(AA32:AE32),0) -> 119 | AG32: =ROUND(AF32/2,0) -> 60 | AI32: 21 | AJ32: 48 | AK32: 19 | AL32: 19 | AM32: 57 | AN32: =ROUND(SUM(AI32:AM32),0) -> 164 | AO32: =ROUND(AN32/2,0) -> 82 | AQ32: 11 | AR32: 25 | AS32: 3 | AT32: 28 | AU32: 10 | AV32: 22.5 | AW32: 7.5 | AX32: 28 | AY32: =ROUND(AQ32+AU32,0) -> 21 | AZ32: =ROUND(AR32+AV32,0) -> 48 | BA32: =ROUND(AS32+AW32,0) -> 11 | BB32: 19 | BC32: =ROUND(AT32+AX32,0) -> 56 | BD32: =SUM(AY32:BC32) -> 155 | BE32: =ROUND(BD32/2,0) -> 78 | BO32: A | BP32: A | BR32: =ROUND(I32+Q32+Y32+AG32+AO32+BE32,0) -> 463 | BS32: =BR32/6 -> 77.166667 | BT32: =IF(BS32>=75,"GRADE I with Distinction",IF(BS32>=60,"GRADE I",IF(BS32>=45,"GRADE II",IF(BS32>=35,"PASS","FAIL")))) -> GRADE I with Distinction
A33: 28 | B33: MHATRE SHRUTI NILESH | C33: 19 | D33: 30 | E33: 18 | F33: 12 | G33: 59 | H33: =ROUND(SUM(C33:G33),0) -> 138 | I33: =ROUND(H33/2,0) -> 69 | K33: 13 | L33: 38 | M33: 11 | N33: 17 | O33: 57 | P33: =ROUND(SUM(K33:O33),0) -> 136 | Q33: =ROUND(P33/2,0) -> 68 | S33: 24 | T33: 41 | U33: 22 | V33: 19 | W33: 66 | X33: =ROUND(SUM(S33:W33),0) -> 172 | Y33: =ROUND(X33/2,0) -> 86 | AA33: 25 | AB33: 34 | AC33: 16 | AD33: 18 | AE33: 56 | AF33: =ROUND(SUM(AA33:AE33),0) -> 149 | AG33: =ROUND(AF33/2,0) -> 75 | AI33: 22 | AJ33: 46 | AK33: 18 | AL33: 20 | AM33: 54 | AN33: =ROUND(SUM(AI33:AM33),0) -> 160 | AO33: =ROUND(AN33/2,0) -> 80 | AQ33: 12 | AR33: 23 | AS33: 7.5 | AT33: 20 | AU33: 5 | AV33: 16 | AW33: 5 | AX33: 24 | AY33: =ROUND(AQ33+AU33,0) -> 17 | AZ33: =ROUND(AR33+AV33,0) -> 39 | BA33: =ROUND(AS33+AW33,0) -> 13 | BB33: 15 | BC33: =ROUND(AT33+AX33,0) -> 44 | BD33: =SUM(AY33:BC33) -> 128 | BE33: =ROUND(BD33/2,0) -> 64 | BO33: A | BP33: A | BR33: =ROUND(I33+Q33+Y33+AG33+AO33+BE33,0) -> 442 | BS33: =BR33/6 -> 73.666667 | BT33: =IF(BS33>=75,"GRADE I with Distinction",IF(BS33>=60,"GRADE I",IF(BS33>=45,"GRADE II",IF(BS33>=35,"PASS","FAIL")))) -> GRADE I
A34: 29 | B34: PAL TANIA CHANDICHARAN | C34: 15 | D34: 30 | E34: 18 | F34: 16 | G34: 58 | H34: =ROUND(SUM(C34:G34),0) -> 137 | I34: =ROUND(H34/2,0) -> 69 | K34: 14 | L34: 44 | M34: 15 | N34: 18 | O34: 63 | P34: =ROUND(SUM(K34:O34),0) -> 154 | Q34: =ROUND(P34/2,0) -> 77 | S34: 23 | T34: 46 | U34: 21 | V34: 20 | W34: 58 | X34: =ROUND(SUM(S34:W34),0) -> 168 | Y34: =ROUND(X34/2,0) -> 84 | AA34: 22 | AB34: 29 | AC34: 10 | AD34: 16 | AE34: 47 | AF34: =ROUND(SUM(AA34:AE34),0) -> 124 | AG34: =ROUND(AF34/2,0) -> 62 | AI34: 20 | AJ34: 42 | AK34: 22 | AL34: 20 | AM34: 65 | AN34: =ROUND(SUM(AI34:AM34),0) -> 169 | AO34: =ROUND(AN34/2,0) -> 85 | AQ34: 12 | AR34: 24 | AS34: 8.5 | AT34: 28 | AU34: 6.5 | AV34: 22.5 | AW34: 6 | AX34: 32 | AY34: =ROUND(AQ34+AU34,0) -> 19 | AZ34: =ROUND(AR34+AV34,0) -> 47 | BA34: =ROUND(AS34+AW34,0) -> 15 | BB34: 14 | BC34: =ROUND(AT34+AX34,0) -> 60 | BD34: =SUM(AY34:BC34) -> 155 | BE34: =ROUND(BD34/2,0) -> 78 | BO34: A | BP34: A | BR34: =ROUND(I34+Q34+Y34+AG34+AO34+BE34,0) -> 455 | BS34: =BR34/6 -> 75.833333 | BT34: =IF(BS34>=75,"GRADE I with Distinction",IF(BS34>=60,"GRADE I",IF(BS34>=45,"GRADE II",IF(BS34>=35,"PASS","FAIL")))) -> GRADE I with Distinction
A35: 30 | B35: PALOJI MOHAMMAD SAAD AFZAL | C35: 10 | D35: 18 | E35: 13 | F35: 12 | G35: 46 | H35: =ROUND(SUM(C35:G35),0) -> 99 | I35: =ROUND(H35/2,0) -> 50 | K35: 19 | L35: 27 | M35: 9 | N35: 19 | O35: 41 | P35: =ROUND(SUM(K35:O35),0) -> 115 | Q35: =ROUND(P35/2,0) -> 58 | S35: 16 | T35: 38 | U35: 13 | V35: 18 | W35: 55 | X35: =ROUND(SUM(S35:W35),0) -> 140 | Y35: =ROUND(X35/2,0) -> 70 | AA35: 20 | AB35: 31 | AC35: 18 | AD35: 17 | AE35: 42 | AF35: =ROUND(SUM(AA35:AE35),0) -> 128 | AG35: =ROUND(AF35/2,0) -> 64 | AI35: 19 | AJ35: 35 | AK35: 15 | AL35: 16 | AM35: 53 | AN35: =ROUND(SUM(AI35:AM35),0) -> 138 | AO35: =ROUND(AN35/2,0) -> 69 | AQ35: 10 | AR35: 12.5 | AS35: 6 | AT35: 17 | AU35: 12 | AV35: 17.5 | AW35: 3.5 | AX35: 24 | AY35: =ROUND(AQ35+AU35,0) -> 22 | AZ35: =ROUND(AR35+AV35,0) -> 30 | BA35: =ROUND(AS35+AW35,0) -> 10 | BB35: 14 | BC35: =ROUND(AT35+AX35,0) -> 41 | BD35: =SUM(AY35:BC35) -> 117 | BE35: =ROUND(BD35/2,0) -> 59 | BO35: A | BP35: A | BR35: =ROUND(I35+Q35+Y35+AG35+AO35+BE35,0) -> 370 | BS35: =BR35/6 -> 61.666667 | BT35: =IF(BS35>=75,"GRADE I with Distinction",IF(BS35>=60,"GRADE I",IF(BS35>=45,"GRADE II",IF(BS35>=35,"PASS","FAIL")))) -> GRADE I
A36: 31 | B36: PATIL ANUSHKA SANJAY | C36: 20 | D36: 29 | E36: 22 | F36: 14 | G36: 60 | H36: =ROUND(SUM(C36:G36),0) -> 145 | I36: =ROUND(H36/2,0) -> 73 | K36: 21 | L36: 44 | M36: 19 | N36: 19 | O36: 77 | P36: =ROUND(SUM(K36:O36),0) -> 180 | Q36: =ROUND(P36/2,0) -> 90 | S36: 24 | T36: 49 | U36: 23 | V36: 19 | W36: 74 | X36: =ROUND(SUM(S36:W36),0) -> 189 | Y36: =ROUND(X36/2,0) -> 95 | AA36: 23 | AB36: 35 | AC36: 21 | AD36: 19 | AE36: 66 | AF36: =ROUND(SUM(AA36:AE36),0) -> 164 | AG36: =ROUND(AF36/2,0) -> 82 | AI36: 24 | AJ36: 48 | AK36: 25 | AL36: 19 | AM36: 76 | AN36: =ROUND(SUM(AI36:AM36),0) -> 192 | AO36: =ROUND(AN36/2,0) -> 96 | AQ36: 13 | AR36: 22 | AS36: 8 | AT36: 35 | AU36: 9 | AV36: 21.5 | AW36: 7.5 | AX36: 37 | AY36: =ROUND(AQ36+AU36,0) -> 22 | AZ36: =ROUND(AR36+AV36,0) -> 44 | BA36: =ROUND(AS36+AW36,0) -> 16 | BB36: 20 | BC36: =ROUND(AT36+AX36,0) -> 72 | BD36: =SUM(AY36:BC36) -> 174 | BE36: =ROUND(BD36/2,0) -> 87 | BO36: A | BP36: A | BR36: =ROUND(I36+Q36+Y36+AG36+AO36+BE36,0) -> 523 | BS36: =BR36/6 -> 87.166667 | BT36: =IF(BS36>=75,"GRADE I with Distinction",IF(BS36>=60,"GRADE I",IF(BS36>=45,"GRADE II",IF(BS36>=35,"PASS","FAIL")))) -> GRADE I with Distinction
A37: 32 | B37: PATIL RUCHI ANANDA | C37: 14 | D37: 27 | E37: 18 | F37: 16 | G37: 56 | H37: =ROUND(SUM(C37:G37),0) -> 131 | I37: =ROUND(H37/2,0) -> 66 | K37: 14 | L37: 43 | M37: 9 | N37: 18 | O37: 57 | P37: =ROUND(SUM(K37:O37),0) -> 141 | Q37: =ROUND(P37/2,0) -> 71 | S37: 25 | T37: 48 | U37: 20 | V37: 19 | W37: 71 | X37: =ROUND(SUM(S37:W37),0) -> 183 | Y37: =ROUND(X37/2,0) -> 92 | AA37: 22 | AB37: 19 | AC37: 19 | AD37: 19 | AE37: 53 | AF37: =ROUND(SUM(AA37:AE37),0) -> 132 | AG37: =ROUND(AF37/2,0) -> 66 | AI37: 25 | AJ37: 49 | AK37: 22 | AL37: 20 | AM37: 72 | AN37: =ROUND(SUM(AI37:AM37),0) -> 188 | AO37: =ROUND(AN37/2,0) -> 94 | AQ37: 12 | AR37: 16 | AS37: 5.5 | AT37: 20 | AU37: 7 | AV37: 15.5 | AW37: 6.5 | AX37: 17 | AY37: =ROUND(AQ37+AU37,0) -> 19 | AZ37: =ROUND(AR37+AV37,0) -> 32 | BA37: =ROUND(AS37+AW37,0) -> 12 | BB37: 15 | BC37: =ROUND(AT37+AX37,0) -> 37 | BD37: =SUM(AY37:BC37) -> 115 | BE37: =ROUND(BD37/2,0) -> 58 | BO37: A | BP37: A | BR37: =ROUND(I37+Q37+Y37+AG37+AO37+BE37,0) -> 447 | BS37: =BR37/6 -> 74.5 | BT37: =IF(BS37>=75,"GRADE I with Distinction",IF(BS37>=60,"GRADE I",IF(BS37>=45,"GRADE II",IF(BS37>=35,"PASS","FAIL")))) -> GRADE I
A38: 33 | B38: PATIL SHRAWANI GANESH | C38: 15 | D38: 29 | E38: 18 | F38: 16 | G38: 50 | H38: =ROUND(SUM(C38:G38),0) -> 128 | I38: =ROUND(H38/2,0) -> 64 | K38: 13 | L38: 35 | M38: 18 | N38: 19 | O38: 54 | P38: =ROUND(SUM(K38:O38),0) -> 139 | Q38: =ROUND(P38/2,0) -> 70 | S38: 23 | T38: 49 | U38: 19 | V38: 19 | W38: 68 | X38: =ROUND(SUM(S38:W38),0) -> 178 | Y38: =ROUND(X38/2,0) -> 89 | AA38: 25 | AB38: 39 | AC38: 20 | AD38: 17 | AE38: 63 | AF38: =ROUND(SUM(AA38:AE38),0) -> 164 | AG38: =ROUND(AF38/2,0) -> 82 | AI38: 19 | AJ38: 45 | AK38: 18 | AL38: 20 | AM38: 66 | AN38: =ROUND(SUM(AI38:AM38),0) -> 168 | AO38: =ROUND(AN38/2,0) -> 84 | AQ38: 13 | AR38: 20 | AS38: 6.5 | AT38: 33 | AU38: 12 | AV38: 22 | AW38: 6 | AX38: 28 | AY38: =ROUND(AQ38+AU38,0) -> 25 | AZ38: =ROUND(AR38+AV38,0) -> 42 | BA38: =ROUND(AS38+AW38,0) -> 13 | BB38: 20 | BC38: =ROUND(AT38+AX38,0) -> 61 | BD38: =SUM(AY38:BC38) -> 161 | BE38: =ROUND(BD38/2,0) -> 81 | BO38: A | BP38: A | BR38: =ROUND(I38+Q38+Y38+AG38+AO38+BE38,0) -> 470 | BS38: =BR38/6 -> 78.333333 | BT38: =IF(BS38>=75,"GRADE I with Distinction",IF(BS38>=60,"GRADE I",IF(BS38>=45,"GRADE II",IF(BS38>=35,"PASS","FAIL")))) -> GRADE I with Distinction
A39: 34 | B39: PAWAR VEDANT ANANDA | C39: 13 | D39: 27 | E39: 17 | F39: 14 | G39: 55 | H39: =ROUND(SUM(C39:G39),0) -> 126 | I39: =ROUND(H39/2,0) -> 63 | K39: 12 | L39: 42 | M39: 16 | N39: 19 | O39: 59 | P39: =ROUND(SUM(K39:O39),0) -> 148 | Q39: =ROUND(P39/2,0) -> 74 | S39: 20 | T39: 45 | U39: 21 | V39: 20 | W39: 70 | X39: =ROUND(SUM(S39:W39),0) -> 176 | Y39: =ROUND(X39/2,0) -> 88 | AA39: 25 | AB39: 32 | AC39: 21 | AD39: 17 | AE39: 64 | AF39: =ROUND(SUM(AA39:AE39),0) -> 159 | AG39: =ROUND(AF39/2,0) -> 80 | AI39: 17 | AJ39: 48 | AK39: 23 | AL39: 19 | AM39: 71 | AN39: =ROUND(SUM(AI39:AM39),0) -> 178 | AO39: =ROUND(AN39/2,0) -> 89 | AQ39: 13 | AR39: 23 | AS39: 8.5 | AT39: 29 | AU39: 10 | AV39: 19.5 | AW39: 6.5 | AX39: 32 | AY39: =ROUND(AQ39+AU39,0) -> 23 | AZ39: =ROUND(AR39+AV39,0) -> 43 | BA39: =ROUND(AS39+AW39,0) -> 15 | BB39: 20 | BC39: =ROUND(AT39+AX39,0) -> 61 | BD39: =SUM(AY39:BC39) -> 162 | BE39: =ROUND(BD39/2,0) -> 81 | BO39: A | BP39: A | BR39: =ROUND(I39+Q39+Y39+AG39+AO39+BE39,0) -> 475 | BS39: =BR39/6 -> 79.166667 | BT39: =IF(BS39>=75,"GRADE I with Distinction",IF(BS39>=60,"GRADE I",IF(BS39>=45,"GRADE II",IF(BS39>=35,"PASS","FAIL")))) -> GRADE I with Distinction
A40: 35 | B40: PILLAI VAISHNAV SATHYAPAL | C40: 15 | D40: 33 | E40: 18 | F40: 18 | G40: 53 | H40: =ROUND(SUM(C40:G40),0) -> 137 | I40: =ROUND(H40/2,0) -> 69 | K40: 16 | L40: 45 | M40: 14 | N40: 18 | O40: 58 | P40: =ROUND(SUM(K40:O40),0) -> 151 | Q40: =ROUND(P40/2,0) -> 76 | S40: 25 | T40: 45 | U40: 21 | V40: 20 | W40: 74 | X40: =ROUND(SUM(S40:W40),0) -> 185 | Y40: =ROUND(X40/2,0) -> 93 | AA40: 24 | AB40: 32 | AC40: 11 | AD40: 18 | AE40: 54 | AF40: =ROUND(SUM(AA40:AE40),0) -> 139 | AG40: =ROUND(AF40/2,0) -> 70 | AI40: 22 | AJ40: 48 | AK40: 17 | AL40: 20 | AM40: 69 | AN40: =ROUND(SUM(AI40:AM40),0) -> 176 | AO40: =ROUND(AN40/2,0) -> 88 | AQ40: 13 | AR40: 23 | AS40: 6 | AT40: 34 | AU40: 10.5 | AV40: 20.5 | AW40: 8 | AX40: 35 | AY40: =ROUND(AQ40+AU40,0) -> 24 | AZ40: =ROUND(AR40+AV40,0) -> 44 | BA40: =ROUND(AS40+AW40,0) -> 14 | BB40: 20 | BC40: =ROUND(AT40+AX40,0) -> 69 | BD40: =SUM(AY40:BC40) -> 171 | BE40: =ROUND(BD40/2,0) -> 86 | BO40: A | BP40: A | BR40: =ROUND(I40+Q40+Y40+AG40+AO40+BE40,0) -> 482 | BS40: =BR40/6 -> 80.333333 | BT40: =IF(BS40>=75,"GRADE I with Distinction",IF(BS40>=60,"GRADE I",IF(BS40>=45,"GRADE II",IF(BS40>=35,"PASS","FAIL")))) -> GRADE I with Distinction
A41: 36 | B41: POOJARI BHUVITH VENKKAPPA | C41: 19 | D41: 28 | E41: 17 | F41: 16 | G41: 54 | H41: =ROUND(SUM(C41:G41),0) -> 134 | I41: =ROUND(H41/2,0) -> 67 | K41: 23 | L41: 43 | M41: 16 | N41: 19 | O41: 74 | P41: =ROUND(SUM(K41:O41),0) -> 175 | Q41: =ROUND(P41/2,0) -> 88 | S41: 25 | T41: 44 | U41: 21 | V41: 20 | W41: 70 | X41: =ROUND(SUM(S41:W41),0) -> 180 | Y41: =ROUND(X41/2,0) -> 90 | AA41: 22 | AB41: 42 | AC41: 22 | AD41: 17 | AE41: 50 | AF41: =ROUND(SUM(AA41:AE41),0) -> 153 | AG41: =ROUND(AF41/2,0) -> 77 | AI41: 25 | AJ41: 47 | AK41: 21 | AL41: 20 | AM41: 70 | AN41: =ROUND(SUM(AI41:AM41),0) -> 183 | AO41: =ROUND(AN41/2,0) -> 92 | AQ41: 13 | AR41: 20.5 | AS41: 9 | AT41: 32 | AU41: 11 | AV41: 23 | AW41: 11 | AX41: 33 | AY41: =ROUND(AQ41+AU41,0) -> 24 | AZ41: =ROUND(AR41+AV41,0) -> 44 | BA41: =ROUND(AS41+AW41,0) -> 20 | BB41: 20 | BC41: =ROUND(AT41+AX41,0) -> 65 | BD41: =SUM(AY41:BC41) -> 173 | BE41: =ROUND(BD41/2,0) -> 87 | BO41: B | BP41: A | BR41: =ROUND(I41+Q41+Y41+AG41+AO41+BE41,0) -> 501 | BS41: =BR41/6 -> 83.5 | BT41: =IF(BS41>=75,"GRADE I with Distinction",IF(BS41>=60,"GRADE I",IF(BS41>=45,"GRADE II",IF(BS41>=35,"PASS","FAIL")))) -> GRADE I with Distinction
A42: 37 | B42: PRADEEP PATEL | C42: 7 | D42: 25 | E42: 13 | F42: 14 | G42: 46 | H42: =ROUND(SUM(C42:G42),0) -> 105 | I42: =ROUND(H42/2,0) -> 53 | K42: 21 | L42: 37 | M42: 12 | N42: 17 | O42: 65 | P42: =ROUND(SUM(K42:O42),0) -> 152 | Q42: =ROUND(P42/2,0) -> 76 | S42: 20 | T42: 45 | U42: 16 | V42: 18 | W42: 60 | X42: =ROUND(SUM(S42:W42),0) -> 159 | Y42: =ROUND(X42/2,0) -> 80 | AA42: 18 | AB42: 32 | AC42: 23 | AD42: 19 | AE42: 41 | AF42: =ROUND(SUM(AA42:AE42),0) -> 133 | AG42: =ROUND(AF42/2,0) -> 67 | AI42: 20 | AJ42: 44 | AK42: 18 | AL42: 20 | AM42: 56 | AN42: =ROUND(SUM(AI42:AM42),0) -> 158 | AO42: =ROUND(AN42/2,0) -> 79 | AQ42: 9 | AR42: 10.5 | AS42: 2 | AT42: 16 | AU42: 7 | AV42: 9.5 | AW42: 4.5 | AX42: 17 | AY42: =ROUND(AQ42+AU42,0) -> 16 | AZ42: =ROUND(AR42+AV42,0) -> 20 | BA42: =ROUND(AS42+AW42,0) -> 7 | BB42: 19 | BC42: =ROUND(AT42+AX42,0) -> 33 | BD42: =SUM(AY42:BC42) -> 95 | BE42: =ROUND(BD42/2,0) -> 48 | BO42: A | BP42: A | BR42: =ROUND(I42+Q42+Y42+AG42+AO42+BE42,0) -> 403 | BS42: =BR42/6 -> 67.166667 | BT42: =IF(BS42>=75,"GRADE I with Distinction",IF(BS42>=60,"GRADE I",IF(BS42>=45,"GRADE II",IF(BS42>=35,"PASS","FAIL")))) -> GRADE I
... A47: 42 | B47: SHEDAGE MANAS MANGESH | C47: 10 | D47: 28 | E47: 17 | F47: 16 | G47: 50 | H47: =ROUND(SUM(C47:G47),0) -> 121 | I47: =ROUND(H47/2,0) -> 61 | K47: 14 | L47: 37 | M47: 9 | N47: 20 | O47: 42 | P47: =ROUND(SUM(K47:O47),0) -> 122 | Q47: =ROUND(P47/2,0) -> 61 | S47: 17 | T47: 40 | U47: 18 | V47: 18 | W47: 65 | X47: =ROUND(SUM(S47:W47),0) -> 158 | Y47: =ROUND(X47/2,0) -> 79 | AA47: 21 | AB47: 21 | AC47: 11 | AD47: 16 | AE47: 43 | AF47: =ROUND(SUM(AA47:AE47),0) -> 112 | AG47: =ROUND(AF47/2,0) -> 56 | AI47: 11 | AJ47: 36 | AK47: 15 | AL47: 16 | AM47: 48 | AN47: =ROUND(SUM(AI47:AM47),0) -> 126 | AO47: =ROUND(AN47/2,0) -> 63 | AQ47: 11 | AR47: 14.5 | AS47: 6.5 | AT47: 12 | AU47: 6 | AV47: 15 | AW47: 6.5 | AX47: 16 | AY47: =ROUND(AQ47+AU47,0) -> 17 | AZ47: =ROUND(AR47+AV47,0) -> 30 | BA47: =ROUND(AS47+AW47,0) -> 13 | BB47: 14 | BC47: =ROUND(AT47+AX47,0) -> 28 | BD47: =SUM(AY47:BC47) -> 102 | BE47: =ROUND(BD47/2,0) -> 51 | BO47: A | BP47: A | BR47: =ROUND(I47+Q47+Y47+AG47+AO47+BE47,0) -> 371 | BS47: =BR47/6 -> 61.833333 | BT47: =IF(BS47>=75,"GRADE I with Distinction",IF(BS47>=60,"GRADE I",IF(BS47>=45,"GRADE II",IF(BS47>=35,"PASS","FAIL")))) -> GRADE I
A48: 43 | B48: SHETTY SHREYA RAJENDRA | C48: 6 | D48: 21 | E48: 16 | F48: 17 | G48: 42 | H48: =ROUND(SUM(C48:G48),0) -> 102 | I48: =ROUND(H48/2,0) -> 51 | K48: 10 | L48: 32 | M48: 15 | N48: 18 | O48: 48 | P48: =ROUND(SUM(K48:O48),0) -> 123 | Q48: =ROUND(P48/2,0) -> 62 | S48: 21 | T48: 45 | U48: 15 | V48: 18 | W48: 68 | X48: =ROUND(SUM(S48:W48),0) -> 167 | Y48: =ROUND(X48/2,0) -> 84 | AA48: 15 | AB48: 23 | AC48: 15 | AD48: 17 | AE48: 25 | AF48: =ROUND(SUM(AA48:AE48),0) -> 95 | AG48: =ROUND(AF48/2,0) -> 48 | AI48: 14 | AJ48: 44 | AK48: 18 | AL48: 18 | AM48: 66 | AN48: =ROUND(SUM(AI48:AM48),0) -> 160 | AO48: =ROUND(AN48/2,0) -> 80 | AQ48: 8 | AR48: 6 | AS48: 3 | AT48: 12 | AU48: 4 | AV48: 7 | AW48: 4.5 | AX48: 4 | AY48: =ROUND(AQ48+AU48,0) -> 12 | AZ48: =ROUND(AR48+AV48,0) -> 13 | BA48: =ROUND(AS48+AW48,0) -> 8 | BB48: 12 | BC48: =ROUND(AT48+AX48,0) -> 16 | BD48: =SUM(AY48:BC48) -> 61 | BE48: =ROUND(BD48/2,0) -> 31 | BF48: 4 | BO48: B | BP48: A | BQ48: 4 | BR48: =ROUND(I48+Q48+Y48+AG48+AO48+BE48,0) -> 356 | BS48: =BR48/6 -> 59.333333 | BT48: PROMOTED
...

Sheet DIV_B
A1: SIES JUNIOR COLLEGE OF COMMERCE, NERUL
A2: FYJC ( DIV B ) MARKSHEET - 2024 - 2025
C3: ENGLISH | K3: HINDI | S3: ECONOMICS | AA3: BK & A/C | AI3: OC | AQ3: MATHS 1 | AU3: MATHS 2 | AY3: Maths Total | BG3: S.P
A4: ROLL NO | B4: STUDENT NAME (AS PER 10TH MARHEET) | C4: ENG UNIT I | D4: ENG TERM I | E4: ENGUNIT II | F4: ENG INT | G4: ENG ANNUAL | H4: ENG TOT | I4: ENG AVG | J4: ENG GRACE | K4: Hindi UNIT I | L4: Hindi TERM I | M4: Hindi UNIT II | N4: Hindi Pract | O4: Hindi Annual | P4: Hindi Total | Q4: Hindi AVG | R4: Hindi GRACE | S4: ECO UNIT I | T4: ECO TERM I | U4: ECO UNIT II | V4: ECO INT | W4: ECO ANNUAL | X4: ECO TOT | Y4: ECO AVG | Z4: ECO GRACE | AA4: BK UNIT I | AB4: BK TERM I | AC4: BK UNIT II | AD4: BK INT | AE4: BK ANNUAL | AF4: BK TOT | AG4: BK AVG | AH4: BK GRACE | AI4: OC UNIT I | AJ4: OC TERM 1 | AK4: OC UNIT II | AL4: OC INT | AM4: OC ANNUAL | AN4: OC TOT | AO4: OC AVG | AP4: OC GRACE | AQ4: MATHS I UNIT I | AR4: MATHS I TERM I | AS4: MATHS I UNIT II | AT4: MATH I ANNUAL | AU4: MATH II UNIT I | AV4: MATH II TERM I | AW4: MATH II UNIT II | AX4: MATH II ANNUAL | AY4: MATHSUNIT I | AZ4: MATHS TERM I | BA4: MATHS UNIT II | BB4: MATHS INT | BC4: MATHS ANNUAL | BD4: MATHS TOT | BE4: MATHS AVG | BF4: MATHS GRACE | BG4: SP UNIT I | BH4: SP TERM I | BI4: SP UNIT II | BJ4: SP INT | BK4: MATHS ANNUAL | BL4: MATHS TOT | BM4: MATHS AVG | BN4: MATHS GRACE | BO4: EVS | BP4: PE | BQ4: Total Grace | BR4: TOTAL | BS4: % | BT4: Result | BU4: Subject
C5: 25 | D5: 50 | E5: 25 | F5: 20 | G5: 80 | H5: 200 | I5: 100 | K5: 25 | L5: 50 | M5: 25 | N5: 20 | O5: 80 | P5: 200 | Q5: 100 | S5: 25 | T5: 50 | U5: 25 | V5: 20 | W5: 80 | X5: 200 | Y5: 100 | AA5: 25 | AB5: 50 | AC5: 25 | AD5: 20 | AE5: 80 | AF5: 200 | AG5: 100 | AI5: 25 | AJ5: 50 | AK5: 25 | AL5: 20 | AM5: 80 | AN5: 200 | AO5: 100 | AQ5: 25 | AR5: 50 | AS5: 25 | AT5: 40 | AU5: 25 | AV5: 50 | AW5: 25 | AX5: 40 | AY5: 25 | AZ5: 50 | BA5: 25 | BB5: 20 | BC5: 80 | BD5: 200 | BE5: 100 | BG5: 25 | BH5: 50 | BI5: 25 | BJ5: 20 | BK5: 80 | BL5: 200 | BM5: 100
A6: 1 | B6: AADYA GIRISH KUMAR | C6: 3 | D6: 11 | E6: 11 | F6: 14 | G6: 51 | H6: =ROUND(SUM(C6:G6),0) -> 90 | I6: =ROUND(H6/2,0) -> 45 | K6: 11 | L6: 9 | M6: 7 | N6: 13 | O6: 23 | P6: =ROUND(SUM(K6:O6),0) -> 63 | Q6: =ROUND(P6/2,0) -> 32 | R6: 3 | S6: 15 | T6: 21 | U6: 10 | V6: 12 | W6: 37 | X6: =ROUND(SUM(S6:W6),0) -> 95 | Y6: =ROUND(X6/2,0) -> 48 | AA6: 21 | AB6: 15 | AC6: 7 | AD6: 11 | AE6: 20 | AF6: =ROUND(SUM(AA6:AE6),0) -> 74 | AG6: =ROUND(AF6/2,0) -> 37 | AI6: 11 | AJ6: 13 | AK6: 10 | AL6: 17 | AM6: 33 | AN6: =ROUND(SUM(AI6:AM6),0) -> 84 | AO6: =ROUND(AN6/2,0) -> 42 | AQ6: 6 | AR6: 1 | AS6: 3 | AT6: 20 | AU6: 4 | AV6: 6 | AW6: 1 | AX6: 10 | AY6: =ROUND(SUM(AQ6,AU6),0) -> 10 | AZ6: =ROUND(SUM(AR6,AV6),0) -> 7 | BA6: =ROUND(SUM(AS6,AW6),0) -> 4 | BB6: 7 | BC6: =ROUND(AT6+AX6,0) -> 30 | BD6: =ROUND(SUM(AY6:BC6),0) -> 58 | BE6: =ROUND(BD6/2,0) -> 29 | BF6: 6 | BO6: B | BP6: A | BQ6: =J6+R6+Z6+AH6+AP6+BF6 -> 9 | BR6: =ROUND(I6+Q6+Y6+AG6+AO6+BE6,0) -> 233 | BS6: =BR6/6 -> 38.833333 | BT6: PROMOTED
A7: 2 | B7: AASHAY AMIT REGE | C7: 8 | D7: 22 | E7: 11 | F7: 12 | G7: 48 | H7: =ROUND(SUM(C7:G7),0) -> 101 | I7: =ROUND(H7/2,0) -> 51 | K7: 14 | L7: 22 | M7: 12 | N7: 13 | O7: 53 | P7: =ROUND(SUM(K7:O7),0) -> 114 | Q7: =ROUND(P7/2,0) -> 57 | S7: 24 | T7: 39 | U7: 16 | V7: 16 | W7: 67 | X7: =ROUND(SUM(S7:W7),0) -> 162 | Y7: =ROUND(X7/2,0) -> 81 | AA7: 22 | AB7: 33 | AC7: 9 | AD7: 16 | AE7: 45 | AF7: =ROUND(SUM(AA7:AE7),0) -> 125 | AG7: =ROUND(AF7/2,0) -> 63 | AI7: 25 | AJ7: 42 | AK7: 19 | AL7: 20 | AM7: 51 | AN7: =ROUND(SUM(AI7:AM7),0) -> 157 | AO7: =ROUND(AN7/2,0) -> 79 | AQ7: 9 | AR7: 16 | AS7: 11 | AT7: 28 | AU7: 4 | AV7: 19 | AW7: 8 | AX7: 17 | AY7: =ROUND(SUM(AQ7,AU7),0) -> 13 | AZ7: =ROUND(SUM(AR7,AV7),0) -> 35 | BA7: =ROUND(SUM(AS7,AW7),0) -> 19 | BB7: 15 | BC7: =ROUND(AT7+AX7,0) -> 45 | BD7: =ROUND(SUM(AY7:BC7),0) -> 127 | BE7: =ROUND(BD7/2,0) -> 64 | BO7: A | BP7: A | BQ7: =J7+R7+Z7+AH7+AP7+BF7 -> 0 | BR7: =ROUND(I7+Q7+Y7+AG7+AO7+BE7,0) -> 395 | BS7: =BR7/6 -> 65.833333 | BT7: =IF(BS7>=75,"GRADE I with Distinction",IF(BS7>=60,"GRADE I",IF(BS7>=45,"GRADE II",IF(BS7>=35,"PASS","FAIL")))) -> GRADE I
A8: 3 | B8: ACHARYA BINDUSHREE BALU | C8: 9 | D8: 11 | E8: 10 | F8: 14 | G8: 36 | H8: =ROUND(SUM(C8:G8),0) -> 80 | I8: =ROUND(H8/2,0) -> 40 | K8: 14 | L8: 18 | M8: 11 | N8: 15 | O8: 29 | P8: =ROUND(SUM(K8:O8),0) -> 87 | Q8: =ROUND(P8/2,0) -> 44 | S8: 15 | T8: 23 | U8: 16 | V8: 11 | W8: 44 | X8: =ROUND(SUM(S8:W8),0) -> 109 | Y8: =ROUND(X8/2,0) -> 55 | AA8: 10 | AB8: 12 | AC8: 7 | AD8: 8 | AE8: 27 | AF8: =ROUND(SUM(AA8:AE8),0) -> 64 | AG8: =ROUND(AF8/2,0) -> 32 | AH8: 3 | AI8: 13 | AJ8: 21 | AK8: 7 | AL8: 18 | AM8: 41 | AN8: =ROUND(SUM(AI8:AM8),0) -> 100 | AO8: =ROUND(AN8/2,0) -> 50 | AQ8: 7 | AR8: 1 | AS8: 4 | AT8: 19 | AU8: 2 | AV8: 4 | AW8: 4 | AX8: 13 | AY8: =ROUND(SUM(AQ8,AU8),0) -> 9 | AZ8: =ROUND(SUM(AR8,AV8),0) -> 5 | BA8: =ROUND(SUM(AS8,AW8),0) -> 8 | BB8: 6 | BC8: =ROUND(AT8+AX8,0) -> 32 | BD8: =ROUND(SUM(AY8:BC8),0) -> 60 | BE8: =ROUND(BD8/2,0) -> 30 | BF8: 5 | BO8: A | BP8: B | BQ8: =J8+R8+Z8+AH8+AP8+BF8 -> 8 | BR8: =ROUND(I8+Q8+Y8+AG8+AO8+BE8,0) -> 251 | BS8: =BR8/6 -> 41.833333 | BT8: PROMOTED
A9: 4 | B9: ADVAIT VIKRAM | C9: 5 | D9: 19 | E9: AB | F9: 12 | G9: 43 | H9: =ROUND(SUM(C9:G9),0) -> 79 | I9: =ROUND(H9/2,0) -> 40 | K9: 6 | L9: 11 | M9: 6 | N9: 14 | O9: 18 | P9: =ROUND(SUM(K9:O9),0) -> 55 | Q9: =ROUND(P9/2,0) -> 28 | R9: 7 | S9: 13 | T9: 33 | U9: AB | V9: 16 | W9: 42 | X9: =ROUND(SUM(S9:W9),0) -> 104 | Y9: =ROUND(X9/2,0) -> 52 | AA9: 13 | AB9: 19 | AC9: 7 | AD9: 15 | AE9: 20 | AF9: =ROUND(SUM(AA9:AE9),0) -> 74 | AG9: =ROUND(AF9/2,0) -> 37 | AI9: 9 | AJ9: 23 | AK9: 3 | AL9: 16 | AM9: 36 | AN9: =ROUND(SUM(AI9:AM9),0) -> 87 | AO9: =ROUND(AN9/2,0) -> 44 | AQ9: 6 | AR9: 3 | AS9: 2 | AT9: 13 | AU9: 4 | AV9: 6 | AW9: 6.5 | AX9: 15 | AY9: =ROUND(SUM(AQ9,AU9),0) -> 10 | AZ9: =ROUND(SUM(AR9,AV9),0) -> 9 | BA9: =ROUND(SUM(AS9,AW9),0) -> 9 | BB9: 9 | BC9: =ROUND(AT9+AX9,0) -> 28 | BD9: =ROUND(SUM(AY9:BC9),0) -> 65 | BE9: =ROUND(BD9/2,0) -> 33 | BF9: 2 | BO9: A | BP9: A | BQ9: =J9+R9+Z9+AH9+AP9+BF9 -> 9 | BR9: =ROUND(I9+Q9+Y9+AG9+AO9+BE9,0) -> 234 | BS9: =BR9/6 -> 39 | BT9: PROMOTED
A10: 5 | B10: AKSHAY KRISHNA KUMAR | C10: 6 | D10: 15 | E10: 11 | F10: 12 | G10: 33 | H10: =ROUND(SUM(C10:G10),0) -> 77 | I10: =ROUND(H10/2,0) -> 39 | K10: 5 | L10: 21 | M10: 8 | N10: 14 | O10: 32 | P10: =ROUND(SUM(K10:O10),0) -> 80 | Q10: =ROUND(P10/2,0) -> 40 | S10: 7 | T10: 23 | U10: 7 | V10: 16 | W10: 28 | X10: =ROUND(SUM(S10:W10),0) -> 81 | Y10: =ROUND(X10/2,0) -> 41 | AA10: 13 | AB10: 17 | AC10: 9 | AD10: 9 | AE10: 24 | AF10: =ROUND(SUM(AA10:AE10),0) -> 72 | AG10: =ROUND(AF10/2,0) -> 36 | AI10: 5 | AJ10: 17 | AK10: 8 | AL10: 15 | AM10: 34 | AN10: =ROUND(SUM(AI10:AM10),0) -> 79 | AO10: =ROUND(AN10/2,0) -> 40 | AQ10: 5 | AR10: 7 | AS10: 3 | AT10: 10 | AU10: 3 | AV10: 6 | AW10: 4.5 | AX10: 12 | AY10: =ROUND(SUM(AQ10,AU10),0) -> 8 | AZ10: =ROUND(SUM(AR10,AV10),0) -> 13 | BA10: =ROUND(SUM(AS10,AW10),0) -> 8 | BB10: 8 | BC10: =ROUND(AT10+AX10,0) -> 22 | BD10: =ROUND(SUM(AY10:BC10),0) -> 59 | BE10: =ROUND(BD10/2,0) -> 30 | BF10: 5 | BO10: B | BP10: B | BQ10: =J10+R10+Z10+AH10+AP10+BF10 -> 5 | BR10: =ROUND(I10+Q10+Y10+AG10+AO10+BE10,0) -> 226 | BS10: =BR10/6 -> 37.666667 | BT10: PROMOTED
A11: 6 | B11: ALOK NAIR | C11: 12 | D11: 26 | E11: 17 | F11: 18 | G11: 61 | H11: =ROUND(SUM(C11:G11),0) -> 134 | I11: =ROUND(H11/2,0) -> 67 | K11: 9 | L11: 28 | M11: 14 | N11: 12 | O11: 51 | P11: =ROUND(SUM(K11:O11),0) -> 114 | Q11: =ROUND(P11/2,0) -> 57 | S11: 16 | T11: 47 | U11: 13 | V11: 17 | W11: 66 | X11: =ROUND(SUM(S11:W11),0) -> 159 | Y11: =ROUND(X11/2,0) -> 80 | AA11: 21 | AB11: 31 | AC11: 12 | AD11: 16 | AE11: 41 | AF11: =ROUND(SUM(AA11:AE11),0) -> 121 | AG11: =ROUND(AF11/2,0) -> 61 | AI11: 13 | AJ11: 43 | AK11: 14 | AL11: 17 | AM11: 59 | AN11: =ROUND(SUM(AI11:AM11),0) -> 146 | AO11: =ROUND(AN11/2,0) -> 73 | AQ11: 12 | AR11: 14 | AS11: 5 | AT11: 20 | AU11: 1 | AV11: 21 | AW11: 4.5 | AX11: 15 | AY11: =ROUND(SUM(AQ11,AU11),0) -> 13 | AZ11: =ROUND(SUM(AR11,AV11),0) -> 35 | BA11: =ROUND(SUM(AS11,AW11),0) -> 10 | BB11: 3 | BC11: =ROUND(AT11+AX11,0) -> 35 | BD11: =ROUND(SUM(AY11:BC11),0) -> 96 | BE11: =ROUND(BD11/2,0) -> 48 | BO11: A | BP11: B | BQ11: =J11+R11+Z11+AH11+AP11+BF11 -> 0 | BR11: =ROUND(I11+Q11+Y11+AG11+AO11+BE11,0) -> 386 | BS11: =BR11/6 -> 64.333333 | BT11: =IF(BS11>=75,"GRADE I with Distinction",IF(BS11>=60,"GRADE I",IF(BS11>=45,"GRADE II",IF(BS11>=35,"PASS","FAIL")))) -> GRADE I
A12: 7 | B12: AMBRE PARTH DHANANJAY | C12: 6 | D12: 15 | E12: 11 | F12: 16 | G12: 45 | H12: =ROUND(SUM(C12:G12),0) -> 93 | I12: =ROUND(H12/2,0) -> 47 | K12: 11 | L12: 22 | M12: 13 | N12: 15 | O12: 43 | P12: =ROUND(SUM(K12:O12),0) -> 104 | Q12: =ROUND(P12/2,0) -> 52 | S12: 13 | T12: 30 | U12: 5 | V12: 18 | W12: 41 | X12: =ROUND(SUM(S12:W12),0) -> 107 | Y12: =ROUND(X12/2,0) -> 54 | AA12: 14 | AB12: 18 | AC12: 10 | AD12: 15 | AE12: 23 | AF12: =ROUND(SUM(AA12:AE12),0) -> 80 | AG12: =ROUND(AF12/2,0) -> 40 | AI12: 10 | AJ12: 18 | AK12: 6 | AL12: 19 | AM12: 41 | AN12: =ROUND(SUM(AI12:AM12),0) -> 94 | AO12: =ROUND(AN12/2,0) -> 47 | AQ12: 8 | AR12: 9 | AS12: 3 | AT12: 17 | AU12: 1 | AV12: 6 | AW12: 3.5 | AX12: 16 | AY12: =ROUND(SUM(AQ12,AU12),0) -> 9 | AZ12: =ROUND(SUM(AR12,AV12),0) -> 15 | BA12: =ROUND(SUM(AS12,AW12),0) -> 7 | BB12: 8 | BC12: =ROUND(AT12+AX12,0) -> 33 | BD12: =ROUND(SUM(AY12:BC12),0) -> 72 | BE12: =ROUND(BD12/2,0) -> 36 | BO12: A | BP12: A | BQ12: =J12+R12+Z12+AH12+AP12+BF12 -> 0 | BR12: =ROUND(I12+Q12+Y12+AG12+AO12+BE12,0) -> 276 | BS12: =BR12/6 -> 46 | BT12: =IF(BS12>=75,"GRADE I with Distinction",IF(BS12>=60,"GRADE I",IF(BS12>=45,"GRADE II",IF(BS12>=35,"PASS","FAIL")))) -> GRADE II
A13: 8 | B13: AMIN NIHAL PREMNATH AMIN | C13: 5 | D13: 5 | E13: 10 | F13: 10 | G13: 30 | H13: =ROUND(SUM(C13:G13),0) -> 60 | I13: =ROUND(H13/2,0) -> 30 | K13: 5 | L13: 17 | M13: 9 | N13: 10 | O13: 21 | P13: =ROUND(SUM(K13:O13),0) -> 62 | Q13: =ROUND(P13/2,0) -> 31 | S13: 8 | T13: 10 | U13: 2 | V13: 11 | W13: 33 | X13: =ROUND(SUM(S13:W13),0) -> 64 | Y13: =ROUND(X13/2,0) -> 32 | AA13: 10 | AB13: 7 | AC13: 8 | AD13: 13 | AE13: 13 | AF13: =ROUND(SUM(AA13:AE13),0) -> 51 | AG13: =ROUND(AF13/2,0) -> 26 | AI13: 7 | AJ13: 14 | AK13: 3 | AL13: 11 | AM13: 19 | AN13: =ROUND(SUM(AI13:AM13),0) -> 54 | AO13: =ROUND(AN13/2,0) -> 27 | AQ13: 4 | AR13: 3 | AS13: 4 | AT13: 12 | AU13: 1 | AV13: 5 | AW13: 2 | AX13: 8 | AY13: =ROUND(SUM(AQ13,AU13),0) -> 5 | AZ13: =ROUND(SUM(AR13,AV13),0) -> 8 | BA13: =ROUND(SUM(AS13,AW13),0) -> 6 | BB13: 5 | BC13: =ROUND(AT13+AX13,0) -> 20 | BD13: =ROUND(SUM(AY13:BC13),0) -> 44 | BE13: =ROUND(BD13/2,0) -> 22 | BO13: C | BP13: B | BQ13: =J13+R13+Z13+AH13+AP13+BF13 -> 0 | BR13: =ROUND(I13+Q13+Y13+AG13+AO13+BE13,0) -> 168 | BS13: =BR13/6 -> 28 | BT13: =IF(BS13>=75,"GRADE I with Distinction",IF(BS13>=60,"GRADE I",IF(BS13>=45,"GRADE II",IF(BS13>=35,"PASS","FAIL")))) -> FAIL
A14: 9 | B14: ANCHAN PRATIK VISHWANATH | C14: 8 | D14: 18 | E14: 11 | F14: 15 | G14: 41 | H14: =ROUND(SUM(C14:G14),0) -> 93 | I14: =ROUND(H14/2,0) -> 47 | K14: 9 | L14: 27 | M14: 11 | N14: 14 | O14: 40 | P14: =ROUND(SUM(K14:O14),0) -> 101 | Q14: =ROUND(P14/2,0) -> 51 | S14: 12 | T14: 32 | U14: 17 | V14: 18 | W14: 58 | X14: =ROUND(SUM(S14:W14),0) -> 137 | Y14: =ROUND(X14/2,0) -> 69 | AA14: 15 | AB14: 18 | AC14: 13 | AD14: 12 | AE14: 27 | AF14: =ROUND(SUM(AA14:AE14),0) -> 85 | AG14: =ROUND(AF14/2,0) -> 43 | AI14: 15 | AJ14: 27 | AK14: 11 | AL14: 17 | AM14: 51 | AN14: =ROUND(SUM(AI14:AM14),0) -> 121 | AO14: =ROUND(AN14/2,0) -> 61 | AQ14: 6 | AR14: 11 | AS14: 5 | AT14: 13 | AU14: 0 | AV14: 7 | AW14: 7 | AX14: 15 | AY14: =ROUND(SUM(AQ14,AU14),0) -> 6 | AZ14: =ROUND(SUM(AR14,AV14),0) -> 18 | BA14: =ROUND(SUM(AS14,AW14),0) -> 12 | BB14: 11 | BC14: =ROUND(AT14+AX14,0) -> 28 | BD14: =ROUND(SUM(AY14:BC14),0) -> 75 | BE14: =ROUND(BD14/2,0) -> 38 | BO14: A | BP14: A | BQ14: =J14+R14+Z14+AH14+AP14+BF14 -> 0 | BR14: =ROUND(I14+Q14+Y14+AG14+AO14+BE14,0) -> 309 | BS14: =BR14/6 -> 51.5 | BT14: =IF(BS14>=75,"GRADE I with Distinction",IF(BS14>=60,"GRADE I",IF(BS14>=45,"GRADE II",IF(BS14>=35,"PASS","FAIL")))) -> GRADE II
A15: 10 | B15: ANMEY VIJAY GHADGE | C15: 7 | D15: 18 | E15: 13 | F15: 14 | G15: 34 | H15: =ROUND(SUM(C15:G15),0) -> 86 | I15: =ROUND(H15/2,0) -> 43 | K15: 9 | L15: 27 | M15: 12 | N15: 14 | O15: 27 | P15: =ROUND(SUM(K15:O15),0) -> 89 | Q15: =ROUND(P15/2,0) -> 45 | S15: 16 | T15: 33 | U15: 18 | V15: 17 | W15: 49 | X15: =ROUND(SUM(S15:W15),0) -> 133 | Y15: =ROUND(X15/2,0) -> 67 | AA15: 15 | AB15: 29 | AC15: 7 | AD15: 14 | AE15: 37 | AF15: =ROUND(SUM(AA15:AE15),0) -> 102 | AG15: =ROUND(AF15/2,0) -> 51 | AI15: 14 | AJ15: 39 | AK15: 9 | AL15: 18 | AM15: 43 | AN15: =ROUND(SUM(AI15:AM15),0) -> 123 | AO15: =ROUND(AN15/2,0) -> 62 | AQ15: 11 | AR15: 16.5 | AS15: 5 | AT15: 22 | AU15: 4 | AV15: 13.5 | AW15: 4.5 | AX15: 21 | AY15: =ROUND(SUM(AQ15,AU15),0) -> 15 | AZ15: =ROUND(SUM(AR15,AV15),0) -> 30 | BA15: =ROUND(SUM(AS15,AW15),0) -> 10 | BB15: 15 | BC15: =ROUND(AT15+AX15,0) -> 43 | BD15: =ROUND(SUM(AY15:BC15),0) -> 113 | BE15: =ROUND(BD15/2,0) -> 57 | BO15: A | BP15: A | BQ15: =J15+R15+Z15+AH15+AP15+BF15 -> 0 | BR15: =ROUND(I15+Q15+Y15+AG15+AO15+BE15,0) -> 325 | BS15: =BR15/6 -> 54.166667 | BT15: =IF(BS15>=75,"GRADE I with Distinction",IF(BS15>=60,"GRADE I",IF(BS15>=45,"GRADE II",IF(BS15>=35,"PASS","FAIL")))) -> GRADE II
A16: 11 | B16: ANUPRIYA SANIL KUMAR | C16: 12 | D16: 29 | E16: 15 | F16: 18 | G16: 56 | H16: =ROUND(SUM(C16:G16),0) -> 130 | I16: =ROUND(H16/2,0) -> 65 | K16: 12 | L16: 26 | M16: 16 | N16: 14 | O16: 38 | P16: =ROUND(SUM(K16:O16),0) -> 106 | Q16: =ROUND(P16/2,0) -> 53 | S16: 22 | T16: 42 | U16: 20 | V16: 15 | W16: 53 | X16: =ROUND(SUM(S16:W16),0) -> 152 | Y16: =ROUND(X16/2,0) -> 76 | AA16: 22 | AB16: 25 | AC16: 11 | AD16: 15 | AE16: 39 | AF16: =ROUND(SUM(AA16:AE16),0) -> 112 | AG16: =ROUND(AF16/2,0) -> 56 | AI16: 14 | AJ16: 41 | AK16: 14 | AL16: 20 | AM16: 55 | AN16: =ROUND(SUM(AI16:AM16),0) -> 144 | AO16: =ROUND(AN16/2,0) -> 72 | AQ16: 12 | AR16: 20 | AS16: 4 | AT16: 29 | AU16: 8.5 | AV16: 9.5 | AW16: 7 | AX16: 8 | AY16: =ROUND(SUM(AQ16,AU16),0) -> 21 | AZ16: =ROUND(SUM(AR16,AV16),0) -> 30 | BA16: =ROUND(SUM(AS16,AW16),0) -> 11 | BB16: 15 | BC16: =ROUND(AT16+AX16,0) -> 37 | BD16: =ROUND(SUM(AY16:BC16),0) -> 114 | BE16: =ROUND(BD16/2,0) -> 57 | BO16: B | BP16: A | BQ16: =J16+R16+Z16+AH16+AP16+BF16 -> 0 | BR16: =ROUND(I16+Q16+Y16+AG16+AO16+BE16,0) -> 379 | BS16: =BR16/6 -> 63.166667 | BT16: =IF(BS16>=75,"GRADE I with Distinction",IF(BS16>=60,"GRADE I",IF(BS16>=45,"GRADE II",IF(BS16>=35,"PASS","FAIL")))) -> GRADE I
A17: 12 | B17: ARYAN SREEDHAR NAIR | C17: 7 | D17: 5 | E17: 10 | F17: 11 | G17: 38 | H17: =ROUND(SUM(C17:G17),0) -> 71 | I17: =ROUND(H17/2,0) -> 36 | K17: 7 | L17: 10 | M17: 9 | N17: 13 | O17: 22 | P17: =ROUND(SUM(K17:O17),0) -> 61 | Q17: =ROUND(P17/2,0) -> 31 | S17: 9 | T17: 16 | U17: 6 | V17: 16 | W17: 24 | X17: =ROUND(SUM(S17:W17),0) -> 71 | Y17: =ROUND(X17/2,0) -> 36 | AA17: 10 | AB17: 6 | AC17: 4 | AD17: 5 | AE17: 7 | AF17: =ROUND(SUM(AA17:AE17),0) -> 32 | AG17: =ROUND(AF17/2,0) -> 16 | AI17: 4 | AJ17: 12 | AK17: 5 | AL17: 12 | AM17: 20 | AN17: =ROUND(SUM(AI17:AM17),0) -> 53 | AO17: =ROUND(AN17/2,0) -> 27 | AQ17: 2 | AR17: 1 | AS17: 4 | AT17: 6 | AU17: 7 | AV17: 2 | AW17: 3 | AX17: 5 | AY17: =ROUND(SUM(AQ17,AU17),0) -> 9 | AZ17: =ROUND(SUM(AR17,AV17),0) -> 3 | BA17: =ROUND(SUM(AS17,AW17),0) -> 7 | BB17: 5 | BC17: =ROUND(AT17+AX17,0) -> 11 | BD17: =ROUND(SUM(AY17:BC17),0) -> 35 | BE17: =ROUND(BD17/2,0) -> 18 | BO17: A | BP17: B | BQ17: =J17+R17+Z17+AH17+AP17+BF17 -> 0 | BR17: =ROUND(I17+Q17+Y17+AG17+AO17+BE17,0) -> 164 | BS17: =BR17/6 -> 27.333333 | BT17: =IF(BS17>=75,"GRADE I with Distinction",IF(BS17>=60,"GRADE I",IF(BS17>=45,"GRADE II",IF(BS17>=35,"PASS","FAIL")))) -> FAIL
A18: 13 | B18: ASHWINIRAI PALARAMAN | C18: 5 | D18: 10 | E18: 9 | F18: 14 | G18: 37 | H18: =ROUND(SUM(C18:G18),0) -> 75 | I18: =ROUND(H18/2,0) -> 38 | K18: 7 | L18: 23 | M18: 11 | N18: 12 | O18: 26 | P18: =ROUND(SUM(K18:O18),0) -> 79 | Q18: =ROUND(P18/2,0) -> 40 | S18: 14 | T18: 24 | U18: 11 | V18: 18 | W18: 56 | X18: =ROUND(SUM(S18:W18),0) -> 123 | Y18: =ROUND(X18/2,0) -> 62 | AA18: 13 | AB18: 16 | AC18: 11 | AD18: 15 | AE18: 28 | AF18: =ROUND(SUM(AA18:AE18),0) -> 83 | AG18: =ROUND(AF18/2,0) -> 42 | AI18: 3 | AJ18: 18 | AK18: 10 | AL18: 14 | AM18: 32 | AN18: =ROUND(SUM(AI18:AM18),0) -> 77 | AO18: =ROUND(AN18/2,0) -> 39 | AQ18: 8 | AR18: 5 | AS18: 4 | AT18: 16 | AU18: 3 | AV18: 8.5 | AW18: 2.5 | AX18: 10 | AY18: =ROUND(SUM(AQ18,AU18),0) -> 11 | AZ18: =ROUND(SUM(AR18,AV18),0) -> 14 | BA18: =ROUND(SUM(AS18,AW18),0) -> 7 | BB18: 5 | BC18: =ROUND(AT18+AX18,0) -> 26 | BD18: =ROUND(SUM(AY18:BC18),0) -> 63 | BE18: =ROUND(BD18/2,0) -> 32 | BF18: 3 | BO18: A | BP18: A | BQ18: =J18+R18+Z18+AH18+AP18+BF18 -> 3 | BR18: =ROUND(I18+Q18+Y18+AG18+AO18+BE18,0) -> 253 | BS18: =BR18/6 -> 42.166667 | BT18: PROMOTED
